<robot
  name="stretch_description">
  <link
    name="base_link">
    <inertial>
      <origin
        xyz="-0.113741233255544 -0.000783755517143381 0.0928858111198232"
        rpy="0 0 0" />
      <mass
        value="1.01138852370462" />
      <inertia
        ixx="0.00230950384279439"
        ixy="5.17824902820563E-06"
        ixz="0.000370142282587899"
        iyy="0.00362194734949085"
        iyz="1.23730961427886E-05"
        izz="0.00230659000567094" />
    </inertial>
    <visual>
      <origin
        xyz="0 0 0"
        rpy="0 0 0" />
      <geometry>
        <mesh
          filename="package://stretch_description/meshes/base_link.STL" />
      </geometry>
      <material
        name="">
        <color
          rgba="0.792156862745098 0.819607843137255 0.933333333333333 1" />
      </material>
    </visual>
    <collision>
      <origin
        xyz="0 0 0"
        rpy="0 0 0" />
      <geometry>
        <mesh
          filename="package://stretch_description/meshes/base_link.STL" />
      </geometry>
    </collision>
  </link>
  <link
    name="link_right_wheel">
    <inertial>
      <origin
        xyz="1.25554620866719E-07 3.54748938391491E-07 0.0239581106165019"
        rpy="0 0 0" />
      <mass
        value="0.00356714564938477" />
      <inertia
        ixx="0"
        ixy="0"
        ixz="0"
        iyy="0"
        iyz="0"
        izz="0" />
    </inertial>
    <visual>
      <origin
        xyz="0 0 0"
        rpy="0 0 0" />
      <geometry>
        <mesh
          filename="package://stretch_description/meshes/link_right_wheel.STL" />
      </geometry>
      <material
        name="">
        <color
          rgba="0.792156862745098 0.819607843137255 0.933333333333333 1" />
      </material>
    </visual>
    <collision>
      <origin
        xyz="0 0 0"
        rpy="0 0 0" />
      <geometry>
        <mesh
          filename="package://stretch_description/meshes/link_right_wheel.STL" />
      </geometry>
    </collision>
  </link>
  <joint
    name="joint_right_wheel"
    type="revolute">
    <origin
      xyz="-0.00300000000000034 -0.15765 0.0508000000000004"
      rpy="-1.57079632679489 -1.11022302462516E-16 7.28583859910277E-17" />
    <parent
      link="base_link" />
    <child
      link="link_right_wheel" />
    <axis
      xyz="0 0 -1" />
  </joint>
  <link
    name="link_left_wheel">
    <inertial>
      <origin
        xyz="1.2555462092223E-07 -3.54748938502514E-07 -0.0239581106165035"
        rpy="0 0 0" />
      <mass
        value="0.00356714564938457" />
      <inertia
        ixx="0"
        ixy="0"
        ixz="0"
        iyy="0"
        iyz="0"
        izz="0" />
    </inertial>
    <visual>
      <origin
        xyz="0 0 0"
        rpy="0 0 0" />
      <geometry>
        <mesh
          filename="package://stretch_description/meshes/link_left_wheel.STL" />
      </geometry>
      <material
        name="">
        <color
          rgba="0.792156862745098 0.819607843137255 0.933333333333333 1" />
      </material>
    </visual>
    <collision>
      <origin
        xyz="0 0 0"
        rpy="0 0 0" />
      <geometry>
        <mesh
          filename="package://stretch_description/meshes/link_left_wheel.STL" />
      </geometry>
    </collision>
  </link>
  <joint
    name="joint_left_wheel"
    type="revolute">
    <origin
      xyz="-0.00300000000001899 0.15765 0.0507999999999994"
      rpy="-1.5707963267949 3.16227047920818E-31 7.88745438253713E-16" />
    <parent
      link="base_link" />
    <child
      link="link_left_wheel" />
    <axis
      xyz="0 0 -1" />
  </joint>
  <link
    name="link_aruco_right_base">
    <inertial>
      <origin
        xyz="0 0 -5.00000000014378E-07"
        rpy="0 0 0" />
      <mass
        value="3.59999999990368E-06" />
      <inertia
        ixx="0"
        ixy="0"
        ixz="0"
        iyy="0"
        iyz="0"
        izz="0" />
    </inertial>
    <visual>
      <origin
        xyz="0 0 0"
        rpy="0 0 0" />
      <geometry>
        <mesh
          filename="package://stretch_description/meshes/link_aruco_right_base.STL" />
      </geometry>
      <material
        name="">
        <color
          rgba="0.792156862745098 0.819607843137255 0.933333333333333 1" />
      </material>
    </visual>
    <collision>
      <origin
        xyz="0 0 0"
        rpy="0 0 0" />
      <geometry>
        <mesh
          filename="package://stretch_description/meshes/link_aruco_right_base.STL" />
      </geometry>
    </collision>
  </link>
  <joint
    name="joint_aruco_right_base"
    type="fixed">
    <origin
      xyz="-0.00500000000000014 -0.1304972 0.1597482"
      rpy="0 0 -1.5707963267949" />
    <parent
      link="base_link" />
    <child
      link="link_aruco_right_base" />
    <axis
      xyz="0 0 0" />
  </joint>
  <link
    name="link_aruco_left_base">
    <inertial>
      <origin
        xyz="0 0 -5.00000000014378E-07"
        rpy="0 0 0" />
      <mass
        value="3.59999999990368E-06" />
      <inertia
        ixx="0"
        ixy="0"
        ixz="0"
        iyy="0"
        iyz="0"
        izz="0" />
    </inertial>
    <visual>
      <origin
        xyz="0 0 0"
        rpy="0 0 0" />
      <geometry>
        <mesh
          filename="package://stretch_description/meshes/link_aruco_left_base.STL" />
      </geometry>
      <material
        name="">
        <color
          rgba="0.792156862745098 0.819607843137255 0.933333333333333 1" />
      </material>
    </visual>
    <collision>
      <origin
        xyz="0 0 0"
        rpy="0 0 0" />
      <geometry>
        <mesh
          filename="package://stretch_description/meshes/link_aruco_left_base.STL" />
      </geometry>
    </collision>
  </link>
  <joint
    name="joint_aruco_left_base"
    type="fixed">
    <origin
      xyz="-0.00500000000000014 0.1304972 0.1597482"
      rpy="0 0 -1.5707963267949" />
    <parent
      link="base_link" />
    <child
      link="link_aruco_left_base" />
    <axis
      xyz="0 0 0" />
  </joint>
  <link
    name="laser">
    <inertial>
      <origin
        xyz="0 0 -0.000755956127492408"
        rpy="0 0 0" />
      <mass
        value="0.0749979022894495" />
      <inertia
        ixx="0"
        ixy="0"
        ixz="0"
        iyy="0"
        iyz="0"
        izz="0" />
    </inertial>
    <visual>
      <origin
        xyz="0 0 0"
        rpy="0 0 0" />
      <geometry>
        <mesh
          filename="package://stretch_description/meshes/laser.STL" />
      </geometry>
      <material
        name="">
        <color
          rgba="0.250980392156863 0.250980392156863 0.250980392156863 1" />
      </material>
    </visual>
    <collision>
      <origin
        xyz="0 0 0"
        rpy="0 0 0" />
      <geometry>
        <mesh
          filename="package://stretch_description/meshes/laser.STL" />
      </geometry>
    </collision>
  </link>
  <joint
    name="joint_laser"
    type="fixed">
    <origin
      xyz="0.000502800000000914 0 0.1664"
      rpy="0 0 -3.14159265358979" />
    <parent
      link="base_link" />
    <child
      link="laser" />
    <axis
      xyz="0 0 0" />
  </joint>
  <link
    name="link_mast">
    <inertial>
      <origin
        xyz="0.00202736379449595 0.738666520812706 0.00190082388524811"
        rpy="0 0 0" />
      <mass
        value="1.91948632911202" />
      <inertia
        ixx="0.037611756666592"
        ixy="-0.00243755562596599"
        ixz="-0.000148664779854962"
        iyy="0.00029794727672244"
        iyz="-0.00228541318930771"
        izz="0.0376309325010985" />
    </inertial>
    <visual>
      <origin
        xyz="0 0 0"
        rpy="0 0 0" />
      <geometry>
        <mesh
          filename="package://stretch_description/meshes/link_mast.STL" />
      </geometry>
      <material
        name="">
        <color
          rgba="0.792156862745098 0.819607843137255 0.933333333333333 1" />
      </material>
    </visual>
    <collision>
      <origin
        xyz="0 0 0"
        rpy="0 0 0" />
      <geometry>
        <mesh
          filename="package://stretch_description/meshes/link_mast.STL" />
      </geometry>
    </collision>
  </link>
  <joint
    name="joint_mast"
    type="fixed">
    <origin
      xyz="-0.07 0.134999999999998 0.0284000000000001"
      rpy="1.5707963267949 0 0.00925318926571245" />
    <parent
      link="base_link" />
    <child
      link="link_mast" />
    <axis
      xyz="0 0 0" />
  </joint>
  <link
    name="link_lift">
    <inertial>
      <origin
        xyz="-0.0566266673550613 0.0304605714719928 0.0116897928421822"
        rpy="0 0 0" />
      <mass
        value="0.329226239397164" />
      <inertia
        ixx="0.00030195040139499"
        ixy="-0.000264360343390532"
        ixz="-0.000133059890302488"
        iyy="0.00124749803141737"
        iyz="-1.57762278264113E-05"
        izz="0.0011055530206975" />
    </inertial>
    <visual>
      <origin
        xyz="0 0 0"
        rpy="0 0 0" />
      <geometry>
        <mesh
          filename="package://stretch_description/meshes/link_lift.STL" />
      </geometry>
      <material
        name="">
        <color
          rgba="0.792156862745098 0.819607843137255 0.933333333333333 1" />
      </material>
    </visual>
    <collision>
      <origin
        xyz="0 0 0"
        rpy="0 0 0" />
      <geometry>
        <mesh
          filename="package://stretch_description/meshes/link_lift.STL" />
      </geometry>
    </collision>
  </link>
  <joint
    name="joint_lift"
    type="prismatic">
    <origin
      xyz="-0.0369217062323472 0.165471199999996 -0.000341653286793524"
      rpy="-1.57079632679552 1.5615431375292 -6.2942004366467E-13" />
    <parent
      link="link_mast" />
    <child
      link="link_lift" />
    <axis
      xyz="0 0 1" />
  </joint>
  <link
    name="link_aruco_shoulder">
    <inertial>
      <origin
        xyz="1.38777878078145E-17 0 -0.000124999999999931"
        rpy="0 0 0" />
      <mass
        value="0.000399141592653546" />
      <inertia
        ixx="0"
        ixy="0"
        ixz="0"
        iyy="0"
        iyz="0"
        izz="0" />
    </inertial>
    <visual>
      <origin
        xyz="0 0 0"
        rpy="0 0 0" />
      <geometry>
        <mesh
          filename="package://stretch_description/meshes/link_aruco_shoulder.STL" />
      </geometry>
      <material
        name="">
        <color
          rgba="0.792156862745098 0.819607843137255 0.933333333333333 1" />
      </material>
    </visual>
    <collision>
      <origin
        xyz="0 0 0"
        rpy="0 0 0" />
      <geometry>
        <mesh
          filename="package://stretch_description/meshes/link_aruco_shoulder.STL" />
      </geometry>
    </collision>
  </link>
  <joint
    name="joint_aruco_shoulder"
    type="fixed">
    <origin
      xyz="-0.013376887637529 0.0558540528812078 0.0861368272417974"
      rpy="-3.55962409571165E-15 -1.50911378375462E-29 -4.23953131897461E-15" />
    <parent
      link="link_lift" />
    <child
      link="link_aruco_shoulder" />
    <axis
      xyz="0 0 0" />
  </joint>
  <link
    name="link_arm_l4">
    <inertial>
      <origin
        xyz="-1.51617165081164E-06 1.4547556735911E-06 -0.089900946600379"
        rpy="0 0 0" />
      <mass
        value="0.071949562667174" />
      <inertia
        ixx="0.000155311520052461"
        ixy="5.126875992306E-13"
        ixz="9.10976968339272E-09"
        iyy="0.000155311520094873"
        iyz="-8.74075776487635E-09"
        izz="1.02625195117338E-12" />
    </inertial>
    <visual>
      <origin
        xyz="0 0 0"
        rpy="0 0 0" />
      <geometry>
        <mesh
          filename="package://stretch_description/meshes/link_arm_l4.STL" />
      </geometry>
      <material
        name="">
        <color
          rgba="0.792156862745098 0.819607843137255 0.933333333333333 1" />
      </material>
    </visual>
    <collision>
      <origin
        xyz="0 0 0"
        rpy="0 0 0" />
      <geometry>
        <mesh
          filename="package://stretch_description/meshes/link_arm_l4.STL" />
      </geometry>
    </collision>
  </link>
  <joint
    name="joint_arm_l4"
    type="fixed">
    <origin
      xyz="-0.254705399999994 0 0"
      rpy="1.57079632679491 -3.10190852906344E-16 -1.5707963267949" />
    <parent
      link="link_lift" />
    <child
      link="link_arm_l4" />
    <axis
      xyz="0 0 0" />
  </joint>
  <link
    name="link_arm_l3">
    <inertial>
      <origin
        xyz="-3.1367674827032E-07 2.95352187817954E-07 -0.0915261629566661"
        rpy="0 0 0" />
      <mass
        value="0.0669285264983502" />
      <inertia
        ixx="0.000149479517877408"
        ixy="2.01377864418297E-14"
        ixz="1.7880010854097E-09"
        iyy="0.000149479517879834"
        iyz="-1.68354853507895E-09"
        izz="4.03485617146839E-14" />
    </inertial>
    <visual>
      <origin
        xyz="0 0 0"
        rpy="0 0 0" />
      <geometry>
        <mesh
          filename="package://stretch_description/meshes/link_arm_l3.STL" />
      </geometry>
      <material
        name="">
        <color
          rgba="0.792156862745098 0.819607843137255 0.933333333333333 1" />
      </material>
    </visual>
    <collision>
      <origin
        xyz="0 0 0"
        rpy="0 0 0" />
      <geometry>
        <mesh
          filename="package://stretch_description/meshes/link_arm_l3.STL" />
      </geometry>
    </collision>
  </link>
  <joint
    name="joint_arm_l3"
    type="prismatic">
    <origin
      xyz="0 0 0.0130000000000043"
      rpy="3.57415596539503E-16 3.21228026482375E-16 -2.45647764837286E-16" />
    <parent
      link="link_arm_l4" />
    <child
      link="link_arm_l3" />
    <axis
      xyz="0 0 1" />
  </joint>
  <link
    name="link_arm_l2">
    <inertial>
      <origin
        xyz="-3.10387605451101E-07 2.93865853651099E-07 -0.0914682423202072"
        rpy="0 0 0" />
      <mass
        value="0.0606945644181059" />
      <inertia
        ixx="0.000135738675101981"
        ixy="1.79245510134926E-14"
        ixz="1.60307399677414E-09"
        iyy="0.000135738675103943"
        iyz="-1.51774329254994E-09"
        izz="3.59027442853823E-14" />
    </inertial>
    <visual>
      <origin
        xyz="0 0 0"
        rpy="0 0 0" />
      <geometry>
        <mesh
          filename="package://stretch_description/meshes/link_arm_l2.STL" />
      </geometry>
      <material
        name="">
        <color
          rgba="0.792156862745098 0.819607843137255 0.933333333333333 1" />
      </material>
    </visual>
    <collision>
      <origin
        xyz="0 0 0"
        rpy="0 0 0" />
      <geometry>
        <mesh
          filename="package://stretch_description/meshes/link_arm_l2.STL" />
      </geometry>
    </collision>
  </link>
  <joint
    name="joint_arm_l2"
    type="prismatic">
    <origin
      xyz="0 0 0.013"
      rpy="2.91385731014123E-16 4.44300759504684E-17 3.25691080516352E-16" />
    <parent
      link="link_arm_l3" />
    <child
      link="link_arm_l2" />
    <axis
      xyz="0 0 1" />
  </joint>
  <link
    name="link_arm_l1">
    <inertial>
      <origin
        xyz="-3.16436750885662E-07 2.87317155012179E-07 -0.0913046520301115"
        rpy="0 0 0" />
      <mass
        value="0.0544820428665958" />
      <inertia
        ixx="0.000122350607529029"
        ixy="1.59058187816316E-14"
        ixz="1.46400904813133E-09"
        iyy="0.000122350607532105"
        iyz="-1.3292859039591E-09"
        izz="3.19599843998205E-14" />
    </inertial>
    <visual>
      <origin
        xyz="0 0 0"
        rpy="0 0 0" />
      <geometry>
        <mesh
          filename="package://stretch_description/meshes/link_arm_l1.STL" />
      </geometry>
      <material
        name="">
        <color
          rgba="0.792156862745098 0.819607843137255 0.933333333333333 1" />
      </material>
    </visual>
    <collision>
      <origin
        xyz="0 0 0"
        rpy="0 0 0" />
      <geometry>
        <mesh
          filename="package://stretch_description/meshes/link_arm_l1.STL" />
      </geometry>
    </collision>
  </link>
  <joint
    name="joint_arm_l1"
    type="prismatic">
    <origin
      xyz="0 0 0.013"
      rpy="7.41596560408007E-17 1.33876788296791E-16 -2.44545873596083E-16" />
    <parent
      link="link_arm_l2" />
    <child
      link="link_arm_l1" />
    <axis
      xyz="0 0 1" />
  </joint>
  <link
    name="link_arm_l0">
    <inertial>
      <origin
        xyz="0.0367135919023473 -0.00107228502450463 -0.0198924766917261"
        rpy="0 0 0" />
      <mass
        value="0.161297657884149" />
      <inertia
        ixx="0.00025761027382777"
        ixy="1.80816099128927E-06"
        ixz="-0.000114893620058452"
        iyy="0.000346600936993365"
        iyz="3.72094843174057E-06"
        izz="8.90993408607343E-05" />
    </inertial>
    <visual>
      <origin
        xyz="0 0 0"
        rpy="0 0 0" />
      <geometry>
        <mesh
          filename="package://stretch_description/meshes/link_arm_l0.STL" />
      </geometry>
      <material
        name="">
        <color
          rgba="0.250980392156863 0.250980392156863 0.250980392156863 1" />
      </material>
    </visual>
    <collision>
      <origin
        xyz="0 0 0"
        rpy="0 0 0" />
      <geometry>
        <mesh
          filename="package://stretch_description/meshes/link_arm_l0.STL" />
      </geometry>
    </collision>
  </link>
  <joint
    name="joint_arm_l0"
    type="prismatic">
    <origin
      xyz="0 0 -0.0137499999999938"
      rpy="-3.05317390622457E-16 -4.23236224076729E-16 -2.68425135229209E-17" />
    <parent
      link="link_arm_l1" />
    <child
      link="link_arm_l0" />
    <axis
      xyz="0 0 1" />
  </joint>
  <link
    name="link_aruco_top_wrist">
    <inertial>
      <origin
        xyz="1.11022302462516E-16 2.77555756156289E-16 -0.00012499999999821"
        rpy="0 0 0" />
      <mass
        value="0.000224999999999975" />
      <inertia
        ixx="0"
        ixy="0"
        ixz="0"
        iyy="0"
        iyz="0"
        izz="0" />
    </inertial>
    <visual>
      <origin
        xyz="0 0 0"
        rpy="0 0 0" />
      <geometry>
        <mesh
          filename="package://stretch_description/meshes/link_aruco_top_wrist.STL" />
      </geometry>
      <material
        name="">
        <color
          rgba="0.792156862745098 0.819607843137255 0.933333333333333 1" />
      </material>
    </visual>
    <collision>
      <origin
        xyz="0 0 0"
        rpy="0 0 0" />
      <geometry>
        <mesh
          filename="package://stretch_description/meshes/link_aruco_top_wrist.STL" />
      </geometry>
    </collision>
  </link>
  <joint
    name="joint_aruco_top_wrist"
    type="fixed">
    <origin
      xyz="0.0472500000000019 0.0292850000000015 0"
      rpy="1.5707963267949 -8.03728587323464E-15 3.14159265358979" />
    <parent
      link="link_arm_l0" />
    <child
      link="link_aruco_top_wrist" />
    <axis
      xyz="0 0 0" />
  </joint>
  <link
    name="link_aruco_inner_wrist">
    <inertial>
      <origin
        xyz="8.32667268468867E-17 1.83186799063151E-15 -0.00012499999999907"
        rpy="0 0 0" />
      <mass
        value="0.000225" />
      <inertia
        ixx="0"
        ixy="0"
        ixz="0"
        iyy="0"
        iyz="0"
        izz="0" />
    </inertial>
    <visual>
      <origin
        xyz="0 0 0"
        rpy="0 0 0" />
      <geometry>
        <mesh
          filename="package://stretch_description/meshes/link_aruco_inner_wrist.STL" />
      </geometry>
      <material
        name="">
        <color
          rgba="0.792156862745098 0.819607843137255 0.933333333333333 1" />
      </material>
    </visual>
    <collision>
      <origin
        xyz="0 0 0"
        rpy="0 0 0" />
      <geometry>
        <mesh
          filename="package://stretch_description/meshes/link_aruco_inner_wrist.STL" />
      </geometry>
    </collision>
  </link>
  <joint
    name="joint_aruco_inner_wrist"
    type="fixed">
    <origin
      xyz="0.0472499999999947 -0.0119000000000034 -0.0272499999991938"
      rpy="3.14159265358979 4.23377442363088E-14 3.14159265358979" />
    <parent
      link="link_arm_l0" />
    <child
      link="link_aruco_inner_wrist" />
    <axis
      xyz="0 0 0" />
  </joint>
  <link
    name="link_wrist_yaw">
    <inertial>
      <origin
        xyz="2.23078222560957E-11 2.09780091804113E-05 -0.0189467005958598"
        rpy="0 0 0" />
      <mass
        value="0.0405398981326229" />
      <inertia
        ixx="2.20067641916353E-09"
        ixy="-3.47385451315509E-19"
        ixz="2.85105099056831E-17"
        iyy="2.20034975236111E-09"
        iyz="2.68100954456647E-11"
        izz="3.26666802418647E-13" />
    </inertial>
    <visual>
      <origin
        xyz="0 0 0"
        rpy="0 0 0" />
      <geometry>
        <mesh
          filename="package://stretch_description/meshes/link_wrist_yaw.STL" />
      </geometry>
      <material
        name="">
        <color
          rgba="0.898039215686275 0.917647058823529 0.929411764705882 1" />
      </material>
    </visual>
    <collision>
      <origin
        xyz="0 0 0"
        rpy="0 0 0" />
      <geometry>
        <mesh
          filename="package://stretch_description/meshes/link_wrist_yaw.STL" />
      </geometry>
    </collision>
  </link>
  <joint
    name="joint_wrist_yaw"
    type="revolute">
    <origin
      xyz="0.0830000000000001 -0.0307500000000003 0"
      rpy="-1.5707963267949 -6.04483156485244E-17 3.14159265358979" />
    <parent
      link="link_arm_l0" />
    <child
      link="link_wrist_yaw" />
    <axis
      xyz="0 0 -1" />
  </joint>
  <link
    name="link_wrist_yaw_bottom">
    <inertial>
      <origin
        xyz="-0.012839 -0.038279 -0.02284"
        rpy="0 0 0" />
      <mass
        value="0.098891" />
      <inertia
        ixx="2.6007E-05"
        ixy="-6.7318E-06"
        ixz="-2.4348E-06"
        iyy="5.9948E-06"
        iyz="-3.3964E-06"
        izz="2.5691E-05" />
    </inertial>
    <visual>
      <origin
        xyz="0 0 0"
        rpy="0 0 0" />
      <geometry>
        <mesh
          filename="package://stretch_description/meshes/link_wrist_yaw_bottom.STL" />
      </geometry>
      <material
        name="">
        <color
          rgba="0.79216 0.81961 0.93333 1" />
      </material>
    </visual>
    <collision>
      <origin
        xyz="0 0 0"
        rpy="0 0 0" />
      <geometry>
        <mesh
          filename="package://stretch_description/meshes/link_wrist_yaw_bottom.STL" />
      </geometry>
    </collision>
  </link>
  <joint
    name="joint_wrist_yaw_bottom"
    type="fixed">
    <origin
      xyz="0 0 0"
      rpy="-3.14159265358979 1.13367999021379E-14 -1.57079632679489" />
    <parent
      link="link_wrist_yaw" />
    <child
      link="link_wrist_yaw_bottom" />
    <axis
      xyz="0 0 0" />
  </joint>
  <link
    name="link_wrist_pitch">
    <inertial>
      <origin
        xyz="-0.0031061 -0.015078 0.020473"
        rpy="0 0 0" />
      <mass
        value="0.070127" />
      <inertia
        ixx="2.5597E-06"
        ixy="-1.4755E-06"
        ixz="-6.3144E-08"
        iyy="3.4397E-06"
        iyz="-4.1781E-07"
        izz="4.5357E-06" />
    </inertial>
    <visual>
      <origin
        xyz="0 0 0"
        rpy="0 0 0" />
      <geometry>
        <mesh
          filename="package://stretch_description/meshes/link_wrist_pitch.STL" />
      </geometry>
      <material
        name="">
        <color
          rgba="0.79216 0.81961 0.93333 1" />
      </material>
    </visual>
    <collision>
      <origin
        xyz="0 0 0"
        rpy="0 0 0" />
      <geometry>
        <mesh
          filename="package://stretch_description/meshes/link_wrist_pitch.STL" />
      </geometry>
    </collision>
  </link>
  <joint
    name="joint_wrist_pitch"
    type="revolute">
    <origin
      xyz="0 -0.0195500000000002 -0.0247499999999984"
      rpy="1.5707963267949 -8.12895570882604E-15 -3.14159265358979" />
    <parent
      link="link_wrist_yaw_bottom" />
    <child
      link="link_wrist_pitch" />
    <axis
      xyz="0 0 1" />
  </joint>
  <link
    name="link_wrist_roll">
    <inertial>
      <origin
        xyz="-9.6312E-15 6.3838E-15 0.0076805"
        rpy="0 0 0" />
      <mass
        value="0.0058567" />
      <inertia
        ixx="0"
        ixy="0"
        ixz="0"
        iyy="0"
        iyz="0"
        izz="0" />
    </inertial>
    <visual>
      <origin
        xyz="0 0 0"
        rpy="0 0 0" />
      <geometry>
        <mesh
          filename="package://stretch_description/meshes/link_wrist_roll.STL" />
      </geometry>
      <material
        name="">
        <color
          rgba="0.79216 0.81961 0.93333 1" />
      </material>
    </visual>
    <collision>
      <origin
        xyz="0 0 0"
        rpy="0 0 0" />
      <geometry>
        <mesh
          filename="package://stretch_description/meshes/link_wrist_roll.STL" />
      </geometry>
    </collision>
  </link>
  <joint
    name="joint_wrist_roll"
    type="revolute">
    <origin
      xyz="-0.0188587444076125 -0.0239999999998942 0.01955"
      rpy="3.14159265358979 -1.5707963267949 0" />
    <parent
      link="link_wrist_pitch" />
    <child
      link="link_wrist_roll" />
    <axis
      xyz="0 0 1" />
  </joint>
  <link
    name="link_straight_gripper">
    <inertial>
      <origin
        xyz="0.0015076 -0.0071158 0.039974"
        rpy="0 0 0" />
      <mass
        value="0.049638" />
      <inertia
        ixx="5.6146E-06"
        ixy="8.2952E-07"
        ixz="-2.4138E-06"
        iyy="1.115E-05"
        iyz="9.7617E-07"
        izz="6.638E-06" />
    </inertial>
    <visual>
      <origin
        xyz="0 0 0"
        rpy="0 0 0" />
      <geometry>
        <mesh
          filename="package://stretch_description/meshes/link_straight_gripper.STL" />
      </geometry>
      <material
        name="">
        <color
          rgba="0.79216 0.81961 0.93333 1" />
      </material>
    </visual>
    <collision>
      <origin
        xyz="0 0 0"
        rpy="0 0 0" />
      <geometry>
        <mesh
          filename="package://stretch_description/meshes/link_straight_gripper.STL" />
      </geometry>
    </collision>
  </link>
  <joint
    name="joint_straight_gripper"
    type="fixed">
    <origin
      xyz="0 0 0.0155"
      rpy="3.54987407349455E-30 3.24021254484265E-20 6.83173341356343E-15" />
    <parent
      link="link_wrist_roll" />
    <child
      link="link_straight_gripper" />
    <axis
      xyz="0 0 0" />
  </joint>
  <link
    name="link_gripper_finger_right">
    <inertial>
      <origin
        xyz="0.094981 0.0080152 1.5543E-15"
        rpy="0 0 0" />
      <mass
        value="0.047621" />
      <inertia
        ixx="0"
        ixy="0"
        ixz="0"
        iyy="0"
        iyz="0"
        izz="0" />
    </inertial>
    <visual>
      <origin
        xyz="0 0 0"
        rpy="0 0 0" />
      <geometry>
        <mesh
          filename="package://stretch_description/meshes/link_gripper_finger_right.STL" />
      </geometry>
      <material
        name="">
        <color
          rgba="0.79216 0.81961 0.93333 1" />
      </material>
    </visual>
    <collision>
      <origin
        xyz="0 0 0"
        rpy="0 0 0" />
      <geometry>
        <mesh
          filename="package://stretch_description/meshes/link_gripper_finger_right.STL" />
      </geometry>
    </collision>
  </link>
  <joint
    name="joint_gripper_finger_right"
    type="revolute">
    <origin
      xyz="-0.0185992414250129 0.00300000000000195 0.0336888959851236"
      rpy="1.5707963267949 -1.5707963267949 0" />
    <parent
      link="link_straight_gripper" />
    <child
      link="link_gripper_finger_right" />
    <axis
      xyz="0 0 -1" />
  </joint>
  <link
    name="link_gripper_fingertip_right">
    <inertial>
      <origin
        xyz="2.8379E-08 6.7513E-09 0.0081258"
        rpy="0 0 0" />
      <mass
        value="0.0038216" />
      <inertia
        ixx="0"
        ixy="0"
        ixz="0"
        iyy="0"
        iyz="0"
        izz="0" />
    </inertial>
    <visual>
      <origin
        xyz="0 0 0"
        rpy="0 0 0" />
      <geometry>
        <mesh
          filename="package://stretch_description/meshes/link_gripper_fingertip_right.STL" />
      </geometry>
      <material
        name="">
        <color
          rgba="0.25098 0.25098 0.25098 1" />
      </material>
    </visual>
    <collision>
      <origin
        xyz="0 0 0"
        rpy="0 0 0" />
      <geometry>
        <mesh
          filename="package://stretch_description/meshes/link_gripper_fingertip_right.STL" />
      </geometry>
    </collision>
  </link>
  <joint
    name="joint_gripper_fingertip_right"
    type="fixed">
    <origin
      xyz="0.190596948563868 0.00604200491758022 0"
      rpy="-1.57079632679483 -3.43320051448326E-14 -2.60113659715756" />
    <parent
      link="link_gripper_finger_right" />
    <child
      link="link_gripper_fingertip_right" />
    <axis
      xyz="0 0 0" />
  </joint>
  <link
    name="link_gripper_finger_left">
    <inertial>
      <origin
        xyz="0.094981 0.0080152 -3.0531E-15"
        rpy="0 0 0" />
      <mass
        value="0.047621" />
      <inertia
        ixx="0"
        ixy="0"
        ixz="0"
        iyy="0"
        iyz="0"
        izz="0" />
    </inertial>
    <visual>
      <origin
        xyz="0 0 0"
        rpy="0 0 0" />
      <geometry>
        <mesh
          filename="package://stretch_description/meshes/link_gripper_finger_left.STL" />
      </geometry>
      <material
        name="">
        <color
          rgba="0.79216 0.81961 0.93333 1" />
      </material>
    </visual>
    <collision>
      <origin
        xyz="0 0 0"
        rpy="0 0 0" />
      <geometry>
        <mesh
          filename="package://stretch_description/meshes/link_gripper_finger_left.STL" />
      </geometry>
    </collision>
  </link>
  <joint
    name="joint_gripper_finger_left"
    type="revolute">
    <origin
      xyz="0.018599 0.003 0.033689"
      rpy="1.5708 -1.5708 0" />
    <parent
      link="link_straight_gripper" />
    <child
      link="link_gripper_finger_left" />
    <axis
      xyz="0 0 1" />
    <limit
      effort="0"
      velocity="0" />
  </joint>
  <link
    name="link_gripper_fingertip_left">
    <inertial>
      <origin
        xyz="-2.595E-08 -6.6561E-09 0.0081258"
        rpy="0 0 0" />
      <mass
        value="0.0038216" />
      <inertia
        ixx="0"
        ixy="0"
        ixz="0"
        iyy="0"
        iyz="0"
        izz="0" />
    </inertial>
    <visual>
      <origin
        xyz="0 0 0"
        rpy="0 0 0" />
      <geometry>
        <mesh
          filename="package://stretch_description/meshes/link_gripper_fingertip_left.STL" />
      </geometry>
      <material
        name="">
        <color
          rgba="0.25098 0.25098 0.25098 1" />
      </material>
    </visual>
    <collision>
      <origin
        xyz="0 0 0"
        rpy="0 0 0" />
      <geometry>
        <mesh
          filename="package://stretch_description/meshes/link_gripper_fingertip_left.STL" />
      </geometry>
    </collision>
  </link>
  <joint
    name="joint_gripper_fingertip_left"
    type="fixed">
    <origin
      xyz="0.1906 0.006042 0"
      rpy="-1.5708 -4.5128E-14 -2.6011" />
    <parent
      link="link_gripper_finger_left" />
    <child
      link="link_gripper_fingertip_left" />
    <axis
      xyz="0 0 0" />
  </joint>
  <link
    name="respeaker_base">
    <inertial>
      <origin
        xyz="0.00765742172691247 0.000780828931965821 -0.00424882981678287"
        rpy="0 0 0" />
      <mass
        value="0.00969129412941469" />
      <inertia
        ixx="4.04210997141847E-07"
        ixy="-2.67330768235355E-08"
        ixz="3.1553354334077E-07"
        iyy="8.95656300986379E-07"
        iyz="3.84519807523386E-08"
        izz="7.08282597380723E-07" />
    </inertial>
    <visual>
      <origin
        xyz="0 0 0"
        rpy="0 0 0" />
      <geometry>
        <mesh
          filename="package://stretch_description/meshes/respeaker_base.STL" />
      </geometry>
      <material
        name="">
        <color
          rgba="0.792156862745098 0.819607843137255 0.933333333333333 1" />
      </material>
    </visual>
    <collision>
      <origin
        xyz="0 0 0"
        rpy="0 0 0" />
      <geometry>
        <mesh
          filename="package://stretch_description/meshes/respeaker_base.STL" />
      </geometry>
    </collision>
  </link>
  <joint
    name="joint_respeaker_base"
    type="fixed">
    <origin
      xyz="1.09074743132875E-05 1.36992 0.00303572796912496"
      rpy="-1.5707963267949 -0.00925318926570022 2.63787745312379E-16" />
    <parent
      link="link_mast" />
    <child
      link="respeaker_base" />
    <axis
      xyz="0 0 0" />
  </joint>
  <link
    name="link_head">
    <inertial>
      <origin
        xyz="0.0385715085631814 0.0438962979592801 0.028595307907455"
        rpy="0 0 0" />
      <mass
        value="0.112253337408612" />
      <inertia
        ixx="2.02525493348555E-05"
        ixy="4.10612328236778E-07"
        ixz="-3.51294745301546E-06"
        iyy="2.05972547453512E-05"
        iyz="2.3353220375623E-06"
        izz="8.906355912634E-07" />
    </inertial>
    <visual>
      <origin
        xyz="0 0 0"
        rpy="0 0 0" />
      <geometry>
        <mesh
          filename="package://stretch_description/meshes/link_head.STL" />
      </geometry>
      <material
        name="">
        <color
          rgba="0.792156862745098 0.819607843137255 0.933333333333333 1" />
      </material>
    </visual>
    <collision>
      <origin
        xyz="0 0 0"
        rpy="0 0 0" />
      <geometry>
        <mesh
          filename="package://stretch_description/meshes/link_head.STL" />
      </geometry>
    </collision>
  </link>
  <joint
    name="joint_head"
    type="fixed">
    <origin
      xyz="0 1.33 0"
      rpy="1.57079632679553 -1.5615431375292 3.14159265358916" />
    <parent
      link="link_mast" />
    <child
      link="link_head" />
    <axis
      xyz="0 0 0" />
  </joint>
  <link
    name="link_head_pan">
    <inertial>
      <origin
        xyz="-0.000897771303919936 0.0153115884262233 -0.00355732352622673"
        rpy="0 0 0" />
      <mass
        value="0.0328380131609749" />
      <inertia
        ixx="2.48787398158796E-05"
        ixy="2.91297285206608E-07"
        ixz="-5.01434279444834E-07"
        iyy="1.75849676778682E-05"
        iyz="1.11885430948432E-05"
        izz="7.33087635633834E-06" />
    </inertial>
    <visual>
      <origin
        xyz="0 0 0"
        rpy="0 0 0" />
      <geometry>
        <mesh
          filename="package://stretch_description/meshes/link_head_pan.STL" />
      </geometry>
      <material
        name="">
        <color
          rgba="0.792156862745098 0.819607843137255 0.933333333333333 1" />
      </material>
    </visual>
    <collision>
      <origin
        xyz="0 0 0"
        rpy="0 0 0" />
      <geometry>
        <mesh
          filename="package://stretch_description/meshes/link_head_pan.STL" />
      </geometry>
    </collision>
  </link>
  <joint
    name="joint_head_pan"
    type="revolute">
    <origin
      xyz="0.134999999999989 0.0731000000000006 -0.00299999999999856"
      rpy="-6.49856749449342E-15 -6.06803104015142E-24 1.5707963267949" />
    <parent
      link="link_head" />
    <child
      link="link_head_pan" />
    <axis
      xyz="0 0 1" />
  </joint>
  <link
    name="link_head_tilt">
    <inertial>
      <origin
        xyz="0.00908913511338216 -0.027465225090576 0.0306590948672528"
        rpy="0 0 0" />
      <mass
        value="0.0695347460282181" />
      <inertia
        ixx="1.73800009347399E-05"
        ixy="1.68303583132773E-07"
        ixz="8.07986814374804E-08"
        iyy="4.1164466083746E-05"
        iyz="-9.46859763966105E-07"
        izz="2.38902030791118E-05" />
    </inertial>
    <visual>
      <origin
        xyz="0 0 0"
        rpy="0 0 0" />
      <geometry>
        <mesh
          filename="package://stretch_description/meshes/link_head_tilt.STL" />
      </geometry>
      <material
        name="">
        <color
          rgba="0.792156862745098 0.819607843137255 0.933333333333333 1" />
      </material>
    </visual>
    <collision>
      <origin
        xyz="0 0 0"
        rpy="0 0 0" />
      <geometry>
        <mesh
          filename="package://stretch_description/meshes/link_head_tilt.STL" />
      </geometry>
    </collision>
  </link>
  <joint
    name="joint_head_tilt"
    type="revolute">
    <origin
      xyz="-0.00130000000000119 0.0275069453864393 -0.0533107921694964"
      rpy="1.5707963267949 -9.10382879585826E-15 9.3735145253564E-16" />
    <parent
      link="link_head_pan" />
    <child
      link="link_head_tilt" />
    <axis
      xyz="0 0 1" />
  </joint>
  <link
    name="link_camera">
    <inertial>
      <origin
        xyz="-0.0452810841870982 0.777061826561632 -0.0993755931555249"
        rpy="0 0 0" />
      <mass
        value="4.42269821655146" />
      <inertia
        ixx="0.951119529846119"
        ixy="-0.108805747599507"
        ixz="-0.00220570102057927"
        iyy="0.0851677453189018"
        iyz="0.0405071934594643"
        izz="0.997333864722933" />
    </inertial>
    <visual>
      <origin
        xyz="0 0 0"
        rpy="0 0 0" />
      <geometry>
        <mesh
          filename="package://stretch_description/meshes/link_camera.STL" />
      </geometry>
      <material
        name="">
        <color
          rgba="0.792156862745098 0.819607843137255 0.933333333333333 1" />
      </material>
    </visual>
    <collision>
      <origin
        xyz="0 0 0"
        rpy="0 0 0" />
      <geometry>
        <mesh
          filename="package://stretch_description/meshes/link_camera.STL" />
      </geometry>
    </collision>
  </link>
  <joint
    name="joint_camera"
    type="fixed">
    <origin
      xyz="0.0202499967221214 -0.0342500000000514 0.0305069453864401"
      rpy="0 -1.5707963267949 0" />
    <parent
      link="link_head_tilt" />
    <child
      link="link_camera" />
    <axis
      xyz="0 0 0" />
  </joint>
</robot>