<robot
  name="stretch_description">
  <link
    name="base_link">
    <inertial>
      <origin
        xyz="-0.113741233255544 -0.000783755517143353 0.0928858111198232"
        rpy="0 0 0" />
      <mass
        value="1.01138852370461" />
      <inertia
        ixx="0.00230950384279439"
        ixy="5.17824902820542E-06"
        ixz="0.000370142282587899"
        iyy="0.00362194734949085"
        iyz="1.23730961427885E-05"
        izz="0.00230659000567094" />
    </inertial>
    <visual>
      <origin
        xyz="0 0 0"
        rpy="0 0 0" />
      <geometry>
        <mesh
          filename="package://stretch_description/meshes/base_link.STL" />
      </geometry>
      <material
        name="">
        <color
          rgba="0.792156862745098 0.819607843137255 0.933333333333333 1" />
      </material>
    </visual>
    <collision>
      <origin
        xyz="0 0 0"
        rpy="0 0 0" />
      <geometry>
        <mesh
          filename="package://stretch_description/meshes/base_link.STL" />
      </geometry>
    </collision>
  </link>
  <link
    name="link_right_wheel">
    <inertial>
      <origin
        xyz="1.25554620866719E-07 3.54748938391491E-07 0.0239581106165018"
        rpy="0 0 0" />
      <mass
        value="0.00356714564938477" />
      <inertia
        ixx="0"
        ixy="0"
        ixz="0"
        iyy="0"
        iyz="0"
        izz="0" />
    </inertial>
    <visual>
      <origin
        xyz="0 0 0"
        rpy="0 0 0" />
      <geometry>
        <mesh
          filename="package://stretch_description/meshes/link_right_wheel.STL" />
      </geometry>
      <material
        name="">
        <color
          rgba="0.792156862745098 0.819607843137255 0.933333333333333 1" />
      </material>
    </visual>
    <collision>
      <origin
        xyz="0 0 0"
        rpy="0 0 0" />
      <geometry>
        <mesh
          filename="package://stretch_description/meshes/link_right_wheel.STL" />
      </geometry>
    </collision>
  </link>
  <joint
    name="joint_right_wheel"
    type="revolute">
    <origin
      xyz="-0.00300000000000034 -0.15765 0.0508000000000004"
      rpy="-1.57079632679489 -1.11022302462516E-16 7.28583859910277E-17" />
    <parent
      link="base_link" />
    <child
      link="link_right_wheel" />
    <axis
      xyz="0 0 -1" />
  </joint>
  <link
    name="link_left_wheel">
    <inertial>
      <origin
        xyz="1.2555462092223E-07 -3.54748938558025E-07 -0.0239581106165035"
        rpy="0 0 0" />
      <mass
        value="0.00356714564938459" />
      <inertia
        ixx="0"
        ixy="0"
        ixz="0"
        iyy="0"
        iyz="0"
        izz="0" />
    </inertial>
    <visual>
      <origin
        xyz="0 0 0"
        rpy="0 0 0" />
      <geometry>
        <mesh
          filename="package://stretch_description/meshes/link_left_wheel.STL" />
      </geometry>
      <material
        name="">
        <color
          rgba="0.792156862745098 0.819607843137255 0.933333333333333 1" />
      </material>
    </visual>
    <collision>
      <origin
        xyz="0 0 0"
        rpy="0 0 0" />
      <geometry>
        <mesh
          filename="package://stretch_description/meshes/link_left_wheel.STL" />
      </geometry>
    </collision>
  </link>
  <joint
    name="joint_left_wheel"
    type="revolute">
    <origin
      xyz="-0.00300000000001899 0.15765 0.0507999999999994"
      rpy="-1.5707963267949 3.16227047920818E-31 7.88745438253713E-16" />
    <parent
      link="base_link" />
    <child
      link="link_left_wheel" />
    <axis
      xyz="0 0 -1" />
  </joint>
  <link
    name="link_aruco_right_base">
    <inertial>
      <origin
        xyz="0 0 -5.00000000014378E-07"
        rpy="0 0 0" />
      <mass
        value="3.59999999990368E-06" />
      <inertia
        ixx="0"
        ixy="0"
        ixz="0"
        iyy="0"
        iyz="0"
        izz="0" />
    </inertial>
    <visual>
      <origin
        xyz="0 0 0"
        rpy="0 0 0" />
      <geometry>
        <mesh
          filename="package://stretch_description/meshes/link_aruco_right_base.STL" />
      </geometry>
      <material
        name="">
        <color
          rgba="0.792156862745098 0.819607843137255 0.933333333333333 1" />
      </material>
    </visual>
    <collision>
      <origin
        xyz="0 0 0"
        rpy="0 0 0" />
      <geometry>
        <mesh
          filename="package://stretch_description/meshes/link_aruco_right_base.STL" />
      </geometry>
    </collision>
  </link>
  <joint
    name="joint_aruco_right_base"
    type="fixed">
    <origin
      xyz="-0.00500000000000014 -0.1304972 0.1597482"
      rpy="0 0 -1.5707963267949" />
    <parent
      link="base_link" />
    <child
      link="link_aruco_right_base" />
    <axis
      xyz="0 0 0" />
  </joint>
  <link
    name="link_aruco_left_base">
    <inertial>
      <origin
        xyz="0 0 -5.00000000014378E-07"
        rpy="0 0 0" />
      <mass
        value="3.59999999990368E-06" />
      <inertia
        ixx="0"
        ixy="0"
        ixz="0"
        iyy="0"
        iyz="0"
        izz="0" />
    </inertial>
    <visual>
      <origin
        xyz="0 0 0"
        rpy="0 0 0" />
      <geometry>
        <mesh
          filename="package://stretch_description/meshes/link_aruco_left_base.STL" />
      </geometry>
      <material
        name="">
        <color
          rgba="0.792156862745098 0.819607843137255 0.933333333333333 1" />
      </material>
    </visual>
    <collision>
      <origin
        xyz="0 0 0"
        rpy="0 0 0" />
      <geometry>
        <mesh
          filename="package://stretch_description/meshes/link_aruco_left_base.STL" />
      </geometry>
    </collision>
  </link>
  <joint
    name="joint_aruco_left_base"
    type="fixed">
    <origin
      xyz="-0.00500000000000014 0.1304972 0.1597482"
      rpy="0 0 -1.5707963267949" />
    <parent
      link="base_link" />
    <child
      link="link_aruco_left_base" />
    <axis
      xyz="0 0 0" />
  </joint>
  <link
    name="laser">
    <inertial>
      <origin
        xyz="0 0 -0.000755956127492408"
        rpy="0 0 0" />
      <mass
        value="0.0749979022894495" />
      <inertia
        ixx="0"
        ixy="0"
        ixz="0"
        iyy="0"
        iyz="0"
        izz="0" />
    </inertial>
    <visual>
      <origin
        xyz="0 0 0"
        rpy="0 0 0" />
      <geometry>
        <mesh
          filename="package://stretch_description/meshes/laser.STL" />
      </geometry>
      <material
        name="">
        <color
          rgba="0.250980392156863 0.250980392156863 0.250980392156863 1" />
      </material>
    </visual>
    <collision>
      <origin
        xyz="0 0 0"
        rpy="0 0 0" />
      <geometry>
        <mesh
          filename="package://stretch_description/meshes/laser.STL" />
      </geometry>
    </collision>
  </link>
  <joint
    name="joint_laser"
    type="fixed">
    <origin
      xyz="0.000502800000000914 0 0.1664"
      rpy="0 0 -3.14159265358979" />
    <parent
      link="base_link" />
    <child
      link="laser" />
    <axis
      xyz="0 0 0" />
  </joint>
  <link
    name="link_mast">
    <inertial>
      <origin
        xyz="0.00202736379449589 0.738666520812706 0.00190082388524811"
        rpy="0 0 0" />
      <mass
        value="1.91948632911202" />
      <inertia
        ixx="0.037611756666592"
        ixy="-0.00243755562596599"
        ixz="-0.000148664779854962"
        iyy="0.00029794727672244"
        iyz="-0.00228541318930771"
        izz="0.0376309325010985" />
    </inertial>
    <visual>
      <origin
        xyz="0 0 0"
        rpy="0 0 0" />
      <geometry>
        <mesh
          filename="package://stretch_description/meshes/link_mast.STL" />
      </geometry>
      <material
        name="">
        <color
          rgba="0.792156862745098 0.819607843137255 0.933333333333333 1" />
      </material>
    </visual>
    <collision>
      <origin
        xyz="0 0 0"
        rpy="0 0 0" />
      <geometry>
        <mesh
          filename="package://stretch_description/meshes/link_mast.STL" />
      </geometry>
    </collision>
  </link>
  <joint
    name="joint_mast"
    type="fixed">
    <origin
      xyz="-0.07 0.134999999999998 0.0284000000000001"
      rpy="1.5707963267949 0 0.00925318926571245" />
    <parent
      link="base_link" />
    <child
      link="link_mast" />
    <axis
      xyz="0 0 0" />
  </joint>
  <link
    name="link_lift">
    <inertial>
      <origin
        xyz="-0.0566266673550613 0.0304605714719928 0.0116897928421823"
        rpy="0 0 0" />
      <mass
        value="0.329226239397164" />
      <inertia
        ixx="0.000301950401394989"
        ixy="-0.000264360343390532"
        ixz="-0.000133059890302488"
        iyy="0.00124749803141737"
        iyz="-1.57762278264116E-05"
        izz="0.0011055530206975" />
    </inertial>
    <visual>
      <origin
        xyz="0 0 0"
        rpy="0 0 0" />
      <geometry>
        <mesh
          filename="package://stretch_description/meshes/link_lift.STL" />
      </geometry>
      <material
        name="">
        <color
          rgba="0.792156862745098 0.819607843137255 0.933333333333333 1" />
      </material>
    </visual>
    <collision>
      <origin
        xyz="0 0 0"
        rpy="0 0 0" />
      <geometry>
        <mesh
          filename="package://stretch_description/meshes/link_lift.STL" />
      </geometry>
    </collision>
  </link>
  <joint
    name="joint_lift"
    type="prismatic">
    <origin
      xyz="-0.0369217062323472 0.165471199999996 -0.000341653286793524"
      rpy="-1.57079632679552 1.5615431375292 -6.2942004366467E-13" />
    <parent
      link="link_mast" />
    <child
      link="link_lift" />
    <axis
      xyz="0 0 1" />
  </joint>
  <link
    name="link_aruco_shoulder">
    <inertial>
      <origin
        xyz="2.08166817117217E-17 0 -0.000124999999999931"
        rpy="0 0 0" />
      <mass
        value="0.000399141592653546" />
      <inertia
        ixx="0"
        ixy="0"
        ixz="0"
        iyy="0"
        iyz="0"
        izz="0" />
    </inertial>
    <visual>
      <origin
        xyz="0 0 0"
        rpy="0 0 0" />
      <geometry>
        <mesh
          filename="package://stretch_description/meshes/link_aruco_shoulder.STL" />
      </geometry>
      <material
        name="">
        <color
          rgba="0.792156862745098 0.819607843137255 0.933333333333333 1" />
      </material>
    </visual>
    <collision>
      <origin
        xyz="0 0 0"
        rpy="0 0 0" />
      <geometry>
        <mesh
          filename="package://stretch_description/meshes/link_aruco_shoulder.STL" />
      </geometry>
    </collision>
  </link>
  <joint
    name="joint_aruco_shoulder"
    type="fixed">
    <origin
      xyz="-0.013376887637529 0.0558540528812078 0.0861368272417974"
      rpy="-3.55962409571165E-15 -1.50911378375462E-29 -4.23953131897461E-15" />
    <parent
      link="link_lift" />
    <child
      link="link_aruco_shoulder" />
    <axis
      xyz="0 0 0" />
  </joint>
  <link
    name="link_arm_l4">
    <inertial>
      <origin
        xyz="-1.51617165083939E-06 1.45475567353559E-06 -0.089900946600379"
        rpy="0 0 0" />
      <mass
        value="0.071949562667174" />
      <inertia
        ixx="0.000155311520052461"
        ixy="5.1268759922357E-13"
        ixz="9.10976968343214E-09"
        iyy="0.000155311520094873"
        iyz="-8.74075776471867E-09"
        izz="1.02625195116025E-12" />
    </inertial>
    <visual>
      <origin
        xyz="0 0 0"
        rpy="0 0 0" />
      <geometry>
        <mesh
          filename="package://stretch_description/meshes/link_arm_l4.STL" />
      </geometry>
      <material
        name="">
        <color
          rgba="0.792156862745098 0.819607843137255 0.933333333333333 1" />
      </material>
    </visual>
    <collision>
      <origin
        xyz="0 0 0"
        rpy="0 0 0" />
      <geometry>
        <mesh
          filename="package://stretch_description/meshes/link_arm_l4.STL" />
      </geometry>
    </collision>
  </link>
  <joint
    name="joint_arm_l4"
    type="fixed">
    <origin
      xyz="-0.254705399999994 0 0"
      rpy="1.57079632679491 -3.10190852906344E-16 -1.5707963267949" />
    <parent
      link="link_lift" />
    <child
      link="link_arm_l4" />
    <axis
      xyz="0 0 0" />
  </joint>
  <link
    name="link_arm_l3">
    <inertial>
      <origin
        xyz="-3.13676748298075E-07 2.95352187706932E-07 -0.0915261629566661"
        rpy="0 0 0" />
      <mass
        value="0.0669285264983502" />
      <inertia
        ixx="0.000149479517877408"
        ixy="2.01377864413581E-14"
        ixz="1.78800108544695E-09"
        iyy="0.000149479517879834"
        iyz="-1.68354853500445E-09"
        izz="4.0348561713897E-14" />
    </inertial>
    <visual>
      <origin
        xyz="0 0 0"
        rpy="0 0 0" />
      <geometry>
        <mesh
          filename="package://stretch_description/meshes/link_arm_l3.STL" />
      </geometry>
      <material
        name="">
        <color
          rgba="0.792156862745098 0.819607843137255 0.933333333333333 1" />
      </material>
    </visual>
    <collision>
      <origin
        xyz="0 0 0"
        rpy="0 0 0" />
      <geometry>
        <mesh
          filename="package://stretch_description/meshes/link_arm_l3.STL" />
      </geometry>
    </collision>
  </link>
  <joint
    name="joint_arm_l3"
    type="prismatic">
    <origin
      xyz="0 0 0.0130000000000043"
      rpy="3.57415596539503E-16 3.21228026482375E-16 -2.45647764837286E-16" />
    <parent
      link="link_arm_l4" />
    <child
      link="link_arm_l3" />
    <axis
      xyz="0 0 1" />
  </joint>
  <link
    name="link_arm_l2">
    <inertial>
      <origin
        xyz="-3.10387605451101E-07 2.93865853595587E-07 -0.0914682423202072"
        rpy="0 0 0" />
      <mass
        value="0.0606945644181059" />
      <inertia
        ixx="0.000135738675101981"
        ixy="1.79245510126936E-14"
        ixz="1.60307399677414E-09"
        iyy="0.000135738675103943"
        iyz="-1.51774329248229E-09"
        izz="3.59027442838693E-14" />
    </inertial>
    <visual>
      <origin
        xyz="0 0 0"
        rpy="0 0 0" />
      <geometry>
        <mesh
          filename="package://stretch_description/meshes/link_arm_l2.STL" />
      </geometry>
      <material
        name="">
        <color
          rgba="0.792156862745098 0.819607843137255 0.933333333333333 1" />
      </material>
    </visual>
    <collision>
      <origin
        xyz="0 0 0"
        rpy="0 0 0" />
      <geometry>
        <mesh
          filename="package://stretch_description/meshes/link_arm_l2.STL" />
      </geometry>
    </collision>
  </link>
  <joint
    name="joint_arm_l2"
    type="prismatic">
    <origin
      xyz="0 0 0.013"
      rpy="2.91385731014123E-16 4.44300759504684E-17 3.25691080516352E-16" />
    <parent
      link="link_arm_l3" />
    <child
      link="link_arm_l2" />
    <axis
      xyz="0 0 1" />
  </joint>
  <link
    name="link_arm_l1">
    <inertial>
      <origin
        xyz="-3.16436750941174E-07 2.87317154956668E-07 -0.0913046520301114"
        rpy="0 0 0" />
      <mass
        value="0.0544820428665958" />
      <inertia
        ixx="0.000122350607529029"
        ixy="1.59058187820301E-14"
        ixz="1.46400904810084E-09"
        iyy="0.000122350607532105"
        iyz="-1.32928590402008E-09"
        izz="3.1959984400416E-14" />
    </inertial>
    <visual>
      <origin
        xyz="0 0 0"
        rpy="0 0 0" />
      <geometry>
        <mesh
          filename="package://stretch_description/meshes/link_arm_l1.STL" />
      </geometry>
      <material
        name="">
        <color
          rgba="0.792156862745098 0.819607843137255 0.933333333333333 1" />
      </material>
    </visual>
    <collision>
      <origin
        xyz="0 0 0"
        rpy="0 0 0" />
      <geometry>
        <mesh
          filename="package://stretch_description/meshes/link_arm_l1.STL" />
      </geometry>
    </collision>
  </link>
  <joint
    name="joint_arm_l1"
    type="prismatic">
    <origin
      xyz="0 0 0.013"
      rpy="7.41596560408007E-17 1.33876788296791E-16 -2.44545873596083E-16" />
    <parent
      link="link_arm_l2" />
    <child
      link="link_arm_l1" />
    <axis
      xyz="0 0 1" />
  </joint>
  <link
    name="link_arm_l0">
    <inertial>
      <origin
        xyz="0.0367135919023473 -0.00107228502450463 -0.0198924766917261"
        rpy="0 0 0" />
      <mass
        value="0.161297657884149" />
      <inertia
        ixx="0.00025761027382777"
        ixy="1.80816099128927E-06"
        ixz="-0.000114893620058452"
        iyy="0.000346600936993366"
        iyz="3.72094843174057E-06"
        izz="8.90993408607344E-05" />
    </inertial>
    <visual>
      <origin
        xyz="0 0 0"
        rpy="0 0 0" />
      <geometry>
        <mesh
          filename="package://stretch_description/meshes/link_arm_l0.STL" />
      </geometry>
      <material
        name="">
        <color
          rgba="0.250980392156863 0.250980392156863 0.250980392156863 1" />
      </material>
    </visual>
    <collision>
      <origin
        xyz="0 0 0"
        rpy="0 0 0" />
      <geometry>
        <mesh
          filename="package://stretch_description/meshes/link_arm_l0.STL" />
      </geometry>
    </collision>
  </link>
  <joint
    name="joint_arm_l0"
    type="prismatic">
    <origin
      xyz="0 0 -0.0137499999999938"
      rpy="-3.05317390622457E-16 -4.23236224076729E-16 -2.68425135229209E-17" />
    <parent
      link="link_arm_l1" />
    <child
      link="link_arm_l0" />
    <axis
      xyz="0 0 1" />
  </joint>
  <link
    name="link_aruco_top_wrist">
    <inertial>
      <origin
        xyz="1.11022302462516E-16 2.22044604925031E-16 -0.000124999999998154"
        rpy="0 0 0" />
      <mass
        value="0.000224999999999975" />
      <inertia
        ixx="0"
        ixy="0"
        ixz="0"
        iyy="0"
        iyz="0"
        izz="0" />
    </inertial>
    <visual>
      <origin
        xyz="0 0 0"
        rpy="0 0 0" />
      <geometry>
        <mesh
          filename="package://stretch_description/meshes/link_aruco_top_wrist.STL" />
      </geometry>
      <material
        name="">
        <color
          rgba="0.792156862745098 0.819607843137255 0.933333333333333 1" />
      </material>
    </visual>
    <collision>
      <origin
        xyz="0 0 0"
        rpy="0 0 0" />
      <geometry>
        <mesh
          filename="package://stretch_description/meshes/link_aruco_top_wrist.STL" />
      </geometry>
    </collision>
  </link>
  <joint
    name="joint_aruco_top_wrist"
    type="fixed">
    <origin
      xyz="0.0472500000000019 0.0292850000000015 0"
      rpy="1.5707963267949 -8.03728587323464E-15 3.14159265358979" />
    <parent
      link="link_arm_l0" />
    <child
      link="link_aruco_top_wrist" />
    <axis
      xyz="0 0 0" />
  </joint>
  <link
    name="link_aruco_inner_wrist">
    <inertial>
      <origin
        xyz="1.11022302462516E-16 1.77635683940025E-15 -0.000124999999999043"
        rpy="0 0 0" />
      <mass
        value="0.000225" />
      <inertia
        ixx="0"
        ixy="0"
        ixz="0"
        iyy="0"
        iyz="0"
        izz="0" />
    </inertial>
    <visual>
      <origin
        xyz="0 0 0"
        rpy="0 0 0" />
      <geometry>
        <mesh
          filename="package://stretch_description/meshes/link_aruco_inner_wrist.STL" />
      </geometry>
      <material
        name="">
        <color
          rgba="0.792156862745098 0.819607843137255 0.933333333333333 1" />
      </material>
    </visual>
    <collision>
      <origin
        xyz="0 0 0"
        rpy="0 0 0" />
      <geometry>
        <mesh
          filename="package://stretch_description/meshes/link_aruco_inner_wrist.STL" />
      </geometry>
    </collision>
  </link>
  <joint
    name="joint_aruco_inner_wrist"
    type="fixed">
    <origin
      xyz="0.0472499999999947 -0.0119000000000034 -0.0272499999991938"
      rpy="3.14159265358979 4.23377442363088E-14 3.14159265358979" />
    <parent
      link="link_arm_l0" />
    <child
      link="link_aruco_inner_wrist" />
    <axis
      xyz="0 0 0" />
  </joint>
  <link
    name="link_wrist_yaw">
    <inertial>
      <origin
        xyz="2.23078222560957E-11 2.0978009180439E-05 -0.0189467005958599"
        rpy="0 0 0" />
      <mass
        value="0.040539898132623" />
      <inertia
        ixx="2.20067641916367E-09"
        ixy="-3.47385026881281E-19"
        ixz="2.8510475071614E-17"
        iyy="2.20034975236125E-09"
        iyz="2.68100954457004E-11"
        izz="3.26666802419496E-13" />
    </inertial>
    <visual>
      <origin
        xyz="0 0 0"
        rpy="0 0 0" />
      <geometry>
        <mesh
          filename="package://stretch_description/meshes/link_wrist_yaw.STL" />
      </geometry>
      <material
        name="">
        <color
          rgba="0.898039215686275 0.917647058823529 0.929411764705882 1" />
      </material>
    </visual>
    <collision>
      <origin
        xyz="0 0 0"
        rpy="0 0 0" />
      <geometry>
        <mesh
          filename="package://stretch_description/meshes/link_wrist_yaw.STL" />
      </geometry>
    </collision>
  </link>
  <joint
    name="joint_wrist_yaw"
    type="revolute">
    <origin
      xyz="0.0830000000000001 -0.0307500000000003 0"
      rpy="-1.5707963267949 -6.04483156485244E-17 3.14159265358979" />
    <parent
      link="link_arm_l0" />
    <child
      link="link_wrist_yaw" />
    <axis
      xyz="0 0 -1" />
  </joint>
  <link
    name="link_wrist_yaw_bottom">
    <inertial>
      <origin
        xyz="-0.012839101377342 -0.0382787718640741 -0.0228400332263616"
        rpy="0 0 0" />
      <mass
        value="0.0988906816399982" />
      <inertia
        ixx="2.60067866573597E-05"
        ixy="-6.73176267521354E-06"
        ixz="-2.43476436723672E-06"
        iyy="5.99482946819924E-06"
        iyz="-3.396424104924E-06"
        izz="2.56907114334732E-05" />
    </inertial>
    <visual>
      <origin
        xyz="0 0 0"
        rpy="0 0 0" />
      <geometry>
        <mesh
          filename="package://stretch_description/meshes/link_wrist_yaw_bottom.STL" />
      </geometry>
      <material
        name="">
        <color
          rgba="0.792156862745098 0.819607843137255 0.933333333333333 1" />
      </material>
    </visual>
    <collision>
      <origin
        xyz="0 0 0"
        rpy="0 0 0" />
      <geometry>
        <mesh
          filename="package://stretch_description/meshes/link_wrist_yaw_bottom.STL" />
      </geometry>
    </collision>
  </link>
  <joint
    name="joint_wrist_yaw_bottom"
    type="fixed">
    <origin
      xyz="0 0 0"
      rpy="-3.14159265358979 1.13367999021379E-14 -1.57079632679489" />
    <parent
      link="link_wrist_yaw" />
    <child
      link="link_wrist_yaw_bottom" />
    <axis
      xyz="0 0 0" />
  </joint>
  <link
    name="link_wrist_pitch">
    <inertial>
      <origin
        xyz="-0.00310609611067145 -0.0150777141465843 0.02047345879259"
        rpy="0 0 0" />
      <mass
        value="0.0701267146295584" />
      <inertia
        ixx="2.55965614980904E-06"
        ixy="-1.47551515167607E-06"
        ixz="-6.31436085977247E-08"
        iyy="3.43968637386281E-06"
        iyz="-4.17813567208847E-07"
        izz="4.53568668211391E-06" />
    </inertial>
    <visual>
      <origin
        xyz="0 0 0"
        rpy="0 0 0" />
      <geometry>
        <mesh
          filename="package://stretch_description/meshes/link_wrist_pitch.STL" />
      </geometry>
      <material
        name="">
        <color
          rgba="0.792156862745098 0.819607843137255 0.933333333333333 1" />
      </material>
    </visual>
    <collision>
      <origin
        xyz="0 0 0"
        rpy="0 0 0" />
      <geometry>
        <mesh
          filename="package://stretch_description/meshes/link_wrist_pitch.STL" />
      </geometry>
    </collision>
  </link>
  <joint
    name="joint_wrist_pitch"
    type="revolute">
    <origin
      xyz="0 -0.0195500000000002 -0.0247499999999984"
      rpy="1.5707963267949 -8.12895570882604E-15 -3.14159265358979" />
    <parent
      link="link_wrist_yaw_bottom" />
    <child
      link="link_wrist_pitch" />
    <axis
      xyz="0 0 1" />
  </joint>
  <link
    name="link_wrist_roll">
    <inertial>
      <origin
        xyz="9.63118473862323E-15 -6.38378239159465E-15 0.00768048802649798"
        rpy="0 0 0" />
      <mass
        value="0.00585666394358811" />
      <inertia
        ixx="0"
        ixy="0"
        ixz="0"
        iyy="0"
        iyz="0"
        izz="0" />
    </inertial>
    <visual>
      <origin
        xyz="0 0 0"
        rpy="0 0 0" />
      <geometry>
        <mesh
          filename="package://stretch_description/meshes/link_wrist_roll.STL" />
      </geometry>
      <material
        name="">
        <color
          rgba="0.792156862745098 0.819607843137255 0.933333333333333 1" />
      </material>
    </visual>
    <collision>
      <origin
        xyz="0 0 0"
        rpy="0 0 0" />
      <geometry>
        <mesh
          filename="package://stretch_description/meshes/link_wrist_roll.STL" />
      </geometry>
    </collision>
  </link>
  <joint
    name="joint_wrist_roll"
    type="revolute">
    <origin
      xyz="-0.0188587444076125 -0.0239999999998942 0.01955"
      rpy="3.14159265358979 1.5707963267949 0" />
    <parent
      link="link_wrist_pitch" />
    <child
      link="link_wrist_roll" />
    <axis
      xyz="0 0 1" />
  </joint>
  <link
    name="link_straight_gripper">
    <inertial>
      <origin
        xyz="0.00150764845432363 -0.00711581846201292 0.0399737901417757"
        rpy="0 0 0" />
      <mass
        value="0.0496384234458285" />
      <inertia
        ixx="5.61461154156396E-06"
        ixy="8.29518962984225E-07"
        ixz="-2.41382921888192E-06"
        iyy="1.11504692003467E-05"
        iyz="9.76174898123366E-07"
        izz="6.63803357903881E-06" />
    </inertial>
    <visual>
      <origin
        xyz="0 0 0"
        rpy="0 0 0" />
      <geometry>
        <mesh
          filename="package://stretch_description/meshes/link_straight_gripper.STL" />
      </geometry>
      <material
        name="">
        <color
          rgba="0.792156862745098 0.819607843137255 0.933333333333333 1" />
      </material>
    </visual>
    <collision>
      <origin
        xyz="0 0 0"
        rpy="0 0 0" />
      <geometry>
        <mesh
          filename="package://stretch_description/meshes/link_straight_gripper.STL" />
      </geometry>
    </collision>
  </link>
  <joint
    name="joint_straight_gripper"
    type="fixed">
    <origin
      xyz="0 0 0.0155"
      rpy="3.54987407349455E-30 3.24021254484265E-20 -3.14159265358979" />
    <parent
      link="link_wrist_roll" />
    <child
      link="link_straight_gripper" />
    <axis
      xyz="0 0 0" />
  </joint>
  <link
    name="link_gripper_finger_right">
    <inertial>
      <origin
        xyz="-0.0949811095686175 -0.00801522758203033 -2.22044604925031E-16"
        rpy="0 0 0" />
      <mass
        value="0.047620778519948" />
      <inertia
        ixx="0"
        ixy="0"
        ixz="0"
        iyy="0"
        iyz="0"
        izz="0" />
    </inertial>
    <visual>
      <origin
        xyz="0 0 0"
        rpy="0 0 0" />
      <geometry>
        <mesh
          filename="package://stretch_description/meshes/link_gripper_finger_right.STL" />
      </geometry>
      <material
        name="">
        <color
          rgba="0.792156862745098 0.819607843137255 0.933333333333333 1" />
      </material>
    </visual>
    <collision>
      <origin
        xyz="0 0 0"
        rpy="0 0 0" />
      <geometry>
        <mesh
          filename="package://stretch_description/meshes/link_gripper_finger_right.STL" />
      </geometry>
    </collision>
  </link>
  <joint
    name="joint_gripper_finger_right"
    type="revolute">
    <origin
      xyz="-0.0185992414250104 0.00300000000000022 0.0336888959851238"
      rpy="1.5707963267949 1.5707963267949 0" />
    <parent
      link="link_straight_gripper" />
    <child
      link="link_gripper_finger_right" />
    <axis
      xyz="0 0 -1" />
  </joint>
  <link
    name="link_gripper_fingertip_right">
    <inertial>
      <origin
        xyz="2.83785970833783E-08 6.75131661687089E-09 0.00812578923434215"
        rpy="0 0 0" />
      <mass
        value="0.00382160881468841" />
      <inertia
        ixx="0"
        ixy="0"
        ixz="0"
        iyy="0"
        iyz="0"
        izz="0" />
    </inertial>
    <visual>
      <origin
        xyz="0 0 0"
        rpy="0 0 0" />
      <geometry>
        <mesh
          filename="package://stretch_description/meshes/link_gripper_fingertip_right.STL" />
      </geometry>
      <material
        name="">
        <color
          rgba="0.250980392156863 0.250980392156863 0.250980392156863 1" />
      </material>
    </visual>
    <collision>
      <origin
        xyz="0 0 0"
        rpy="0 0 0" />
      <geometry>
        <mesh
          filename="package://stretch_description/meshes/link_gripper_fingertip_right.STL" />
      </geometry>
    </collision>
  </link>
  <joint
    name="joint_gripper_fingertip_right"
    type="fixed">
    <origin
      xyz="-0.190596948563868 -0.00604200491758269 0"
      rpy="-1.57079632679483 -3.43320051448326E-14 0.540456056432235" />
    <parent
      link="link_gripper_finger_right" />
    <child
      link="link_gripper_fingertip_right" />
    <axis
      xyz="0 0 0" />
  </joint>
  <link
    name="link_gripper_finger_left">
    <inertial>
      <origin
        xyz="0.0949811095686164 -0.00801522758203194 1.38777878078145E-15"
        rpy="0 0 0" />
      <mass
        value="0.0476207785199479" />
      <inertia
        ixx="0"
        ixy="0"
        ixz="0"
        iyy="0"
        iyz="0"
        izz="0" />
    </inertial>
    <visual>
      <origin
        xyz="0 0 0"
        rpy="0 0 0" />
      <geometry>
        <mesh
          filename="package://stretch_description/meshes/link_gripper_finger_left.STL" />
      </geometry>
      <material
        name="">
        <color
          rgba="0.792156862745098 0.819607843137255 0.933333333333333 1" />
      </material>
    </visual>
    <collision>
      <origin
        xyz="0 0 0"
        rpy="0 0 0" />
      <geometry>
        <mesh
          filename="package://stretch_description/meshes/link_gripper_finger_left.STL" />
      </geometry>
    </collision>
  </link>
  <joint
    name="joint_gripper_finger_left"
    type="revolute">
    <origin
      xyz="0.0185992414250199 0.0029999999999975 0.0336888959851238"
      rpy="1.5707963267949 -1.5707963267949 0" />
    <parent
      link="link_straight_gripper" />
    <child
      link="link_gripper_finger_left" />
    <axis
      xyz="0 0 -1" />
  </joint>
  <link
    name="link_gripper_fingertip_left">
    <inertial>
      <origin
        xyz="-2.59496317767116E-08 -6.65612598371723E-09 0.00812579036862837"
        rpy="0 0 0" />
      <mass
        value="0.00382160686584851" />
      <inertia
        ixx="0"
        ixy="0"
        ixz="0"
        iyy="0"
        iyz="0"
        izz="0" />
    </inertial>
    <visual>
      <origin
        xyz="0 0 0"
        rpy="0 0 0" />
      <geometry>
        <mesh
          filename="package://stretch_description/meshes/link_gripper_fingertip_left.STL" />
      </geometry>
      <material
        name="">
        <color
          rgba="0.250980392156863 0.250980392156863 0.250980392156863 1" />
      </material>
    </visual>
    <collision>
      <origin
        xyz="0 0 0"
        rpy="0 0 0" />
      <geometry>
        <mesh
          filename="package://stretch_description/meshes/link_gripper_fingertip_left.STL" />
      </geometry>
    </collision>
  </link>
  <joint
    name="joint_gripper_fingertip_left"
    type="fixed">
    <origin
      xyz="0.190596948563868 -0.00604200491773282 0"
      rpy="1.57079632679496 4.51275387511463E-14 2.60113659715756" />
    <parent
      link="link_gripper_finger_left" />
    <child
      link="link_gripper_fingertip_left" />
    <axis
      xyz="0 0 0" />
  </joint>
  <link
    name="respeaker_base">
    <inertial>
      <origin
        xyz="0.00765742172691244 0.000780828931965821 -0.00424882981678287"
        rpy="0 0 0" />
      <mass
        value="0.00969129412941469" />
      <inertia
        ixx="4.04210997141848E-07"
        ixy="-2.6733076823536E-08"
        ixz="3.15533543340771E-07"
        iyy="8.95656300986384E-07"
        iyz="3.84519807523384E-08"
        izz="7.08282597380726E-07" />
    </inertial>
    <visual>
      <origin
        xyz="0 0 0"
        rpy="0 0 0" />
      <geometry>
        <mesh
          filename="package://stretch_description/meshes/respeaker_base.STL" />
      </geometry>
      <material
        name="">
        <color
          rgba="0.792156862745098 0.819607843137255 0.933333333333333 1" />
      </material>
    </visual>
    <collision>
      <origin
        xyz="0 0 0"
        rpy="0 0 0" />
      <geometry>
        <mesh
          filename="package://stretch_description/meshes/respeaker_base.STL" />
      </geometry>
    </collision>
  </link>
  <joint
    name="joint_respeaker_base"
    type="fixed">
    <origin
      xyz="1.09074743132875E-05 1.36992 0.00303572796912496"
      rpy="-1.5707963267949 -0.00925318926570022 2.63787745312379E-16" />
    <parent
      link="link_mast" />
    <child
      link="respeaker_base" />
    <axis
      xyz="0 0 0" />
  </joint>
  <link
    name="link_head">
    <inertial>
      <origin
        xyz="0.0385715085631813 0.0438962979592802 0.0285953079074555"
        rpy="0 0 0" />
      <mass
        value="0.112253337408612" />
      <inertia
        ixx="2.0252549334856E-05"
        ixy="4.10612328236775E-07"
        ixz="-3.5129474530155E-06"
        iyy="2.05972547453517E-05"
        iyz="2.33532203756232E-06"
        izz="8.90635591263395E-07" />
    </inertial>
    <visual>
      <origin
        xyz="0 0 0"
        rpy="0 0 0" />
      <geometry>
        <mesh
          filename="package://stretch_description/meshes/link_head.STL" />
      </geometry>
      <material
        name="">
        <color
          rgba="0.792156862745098 0.819607843137255 0.933333333333333 1" />
      </material>
    </visual>
    <collision>
      <origin
        xyz="0 0 0"
        rpy="0 0 0" />
      <geometry>
        <mesh
          filename="package://stretch_description/meshes/link_head.STL" />
      </geometry>
    </collision>
  </link>
  <joint
    name="joint_head"
    type="fixed">
    <origin
      xyz="0 1.33 0"
      rpy="1.57079632679553 -1.5615431375292 3.14159265358916" />
    <parent
      link="link_mast" />
    <child
      link="link_head" />
    <axis
      xyz="0 0 0" />
  </joint>
  <link
    name="link_head_pan">
    <inertial>
      <origin
        xyz="-0.000897771303919881 0.0153115884262233 -0.00355732352622651"
        rpy="0 0 0" />
      <mass
        value="0.0328380131609749" />
      <inertia
        ixx="2.48787398158797E-05"
        ixy="2.91297285206607E-07"
        ixz="-5.01434279444837E-07"
        iyy="1.75849676778684E-05"
        iyz="1.11885430948433E-05"
        izz="7.33087635633834E-06" />
    </inertial>
    <visual>
      <origin
        xyz="0 0 0"
        rpy="0 0 0" />
      <geometry>
        <mesh
          filename="package://stretch_description/meshes/link_head_pan.STL" />
      </geometry>
      <material
        name="">
        <color
          rgba="0.792156862745098 0.819607843137255 0.933333333333333 1" />
      </material>
    </visual>
    <collision>
      <origin
        xyz="0 0 0"
        rpy="0 0 0" />
      <geometry>
        <mesh
          filename="package://stretch_description/meshes/link_head_pan.STL" />
      </geometry>
    </collision>
  </link>
  <joint
    name="joint_head_pan"
    type="revolute">
    <origin
      xyz="0.134999999999989 0.0731000000000006 -0.00299999999999856"
      rpy="-6.49856749449342E-15 -6.06803104015142E-24 1.5707963267949" />
    <parent
      link="link_head" />
    <child
      link="link_head_pan" />
    <axis
      xyz="0 0 1" />
  </joint>
  <link
    name="link_head_tilt">
    <inertial>
      <origin
        xyz="0.00908913511338216 -0.027465225090576 0.0306590948672528"
        rpy="0 0 0" />
      <mass
        value="0.0695347460282181" />
      <inertia
        ixx="1.73800009347399E-05"
        ixy="1.68303583132773E-07"
        ixz="8.07986814374736E-08"
        iyy="4.1164466083746E-05"
        iyz="-9.46859763966105E-07"
        izz="2.38902030791118E-05" />
    </inertial>
    <visual>
      <origin
        xyz="0 0 0"
        rpy="0 0 0" />
      <geometry>
        <mesh
          filename="package://stretch_description/meshes/link_head_tilt.STL" />
      </geometry>
      <material
        name="">
        <color
          rgba="0.792156862745098 0.819607843137255 0.933333333333333 1" />
      </material>
    </visual>
    <collision>
      <origin
        xyz="0 0 0"
        rpy="0 0 0" />
      <geometry>
        <mesh
          filename="package://stretch_description/meshes/link_head_tilt.STL" />
      </geometry>
    </collision>
  </link>
  <joint
    name="joint_head_tilt"
    type="revolute">
    <origin
      xyz="-0.00130000000000119 0.0275069453864393 -0.0533107921694964"
      rpy="1.5707963267949 -9.10382879585826E-15 9.3735145253564E-16" />
    <parent
      link="link_head_pan" />
    <child
      link="link_head_tilt" />
    <axis
      xyz="0 0 1" />
  </joint>
  <link
    name="link_camera">
    <inertial>
      <origin
        xyz="-0.0452810841870982 0.777061826561633 -0.0993755931555248"
        rpy="0 0 0" />
      <mass
        value="4.42269821655146" />
      <inertia
        ixx="0.951119529846119"
        ixy="-0.108805747599507"
        ixz="-0.00220570102057927"
        iyy="0.0851677453189018"
        iyz="0.0405071934594643"
        izz="0.997333864722933" />
    </inertial>
    <visual>
      <origin
        xyz="0 0 0"
        rpy="0 0 0" />
      <geometry>
        <mesh
          filename="package://stretch_description/meshes/link_camera.STL" />
      </geometry>
      <material
        name="">
        <color
          rgba="0.792156862745098 0.819607843137255 0.933333333333333 1" />
      </material>
    </visual>
    <collision>
      <origin
        xyz="0 0 0"
        rpy="0 0 0" />
      <geometry>
        <mesh
          filename="package://stretch_description/meshes/link_camera.STL" />
      </geometry>
    </collision>
  </link>
  <joint
    name="joint_camera"
    type="fixed">
    <origin
      xyz="0.0202499967221214 -0.0342500000000514 0.0305069453864401"
      rpy="0 -1.5707963267949 0" />
    <parent
      link="link_head_tilt" />
    <child
      link="link_camera" />
    <axis
      xyz="0 0 0" />
  </joint>
</robot>