<robot
  name="stretch_description">
  <link
    name="base_link">
    <inertial>
      <origin
        xyz="-0.113741233255544 -0.000783755517143409 0.0928858111198232"
        rpy="0 0 0" />
      <mass
        value="1.01138852370461" />
      <inertia
        ixx="0.00230950384279438"
        ixy="5.17824902820602E-06"
        ixz="0.000370142282587899"
        iyy="0.00362194734949084"
        iyz="1.23730961427887E-05"
        izz="0.00230659000567094" />
    </inertial>
    <visual>
      <origin
        xyz="0 0 0"
        rpy="0 0 0" />
      <geometry>
        <mesh
          filename="package://stretch_description/meshes/base_link.STL" />
      </geometry>
      <material
        name="">
        <color
          rgba="0.792156862745098 0.819607843137255 0.933333333333333 1" />
      </material>
    </visual>
    <collision>
      <origin
        xyz="0 0 0"
        rpy="0 0 0" />
      <geometry>
        <mesh
          filename="package://stretch_description/meshes/base_link.STL" />
      </geometry>
    </collision>
  </link>
  <link
    name="link_right_wheel">
    <inertial>
      <origin
        xyz="1.25554620866719E-07 3.54748938391491E-07 0.0239581106165018"
        rpy="0 0 0" />
      <mass
        value="0.00356714564938477" />
      <inertia
        ixx="0"
        ixy="0"
        ixz="0"
        iyy="0"
        iyz="0"
        izz="0" />
    </inertial>
    <visual>
      <origin
        xyz="0 0 0"
        rpy="0 0 0" />
      <geometry>
        <mesh
          filename="package://stretch_description/meshes/link_right_wheel.STL" />
      </geometry>
      <material
        name="">
        <color
          rgba="0.792156862745098 0.819607843137255 0.933333333333333 1" />
      </material>
    </visual>
    <collision>
      <origin
        xyz="0 0 0"
        rpy="0 0 0" />
      <geometry>
        <mesh
          filename="package://stretch_description/meshes/link_right_wheel.STL" />
      </geometry>
    </collision>
  </link>
  <joint
    name="joint_right_wheel"
    type="revolute">
    <origin
      xyz="-0.003 -0.15765 0.0508"
      rpy="-1.5708 -1.1102E-16 7.2858E-17" />
    <parent
      link="base_link" />
    <child
      link="link_right_wheel" />
    <axis
      xyz="0 0 -1" />
    <limit
      effort="0"
      velocity="0" />
  </joint>
  <link
    name="link_left_wheel">
    <inertial>
      <origin
        xyz="1.2555E-07 -3.5475E-07 -0.023958"
        rpy="0 0 0" />
      <mass
        value="0.0035671" />
      <inertia
        ixx="0"
        ixy="0"
        ixz="0"
        iyy="0"
        iyz="0"
        izz="0" />
    </inertial>
    <visual>
      <origin
        xyz="0 0 0"
        rpy="0 0 0" />
      <geometry>
        <mesh
          filename="package://stretch_description/meshes/link_left_wheel.STL" />
      </geometry>
      <material
        name="">
        <color
          rgba="0.79216 0.81961 0.93333 1" />
      </material>
    </visual>
    <collision>
      <origin
        xyz="0 0 0"
        rpy="0 0 0" />
      <geometry>
        <mesh
          filename="package://stretch_description/meshes/link_left_wheel.STL" />
      </geometry>
    </collision>
  </link>
  <joint
    name="joint_left_wheel"
    type="revolute">
    <origin
      xyz="-0.003 0.15765 0.0508"
      rpy="-1.5708 3.1623E-31 7.8875E-16" />
    <parent
      link="base_link" />
    <child
      link="link_left_wheel" />
    <axis
      xyz="0 0 -1" />
    <limit
      effort="0"
      velocity="0" />
  </joint>
  <link
    name="link_aruco_right_base">
    <inertial>
      <origin
        xyz="0 0 -5.00000000014378E-07"
        rpy="0 0 0" />
      <mass
        value="3.59999999990368E-06" />
      <inertia
        ixx="0"
        ixy="0"
        ixz="0"
        iyy="0"
        iyz="0"
        izz="0" />
    </inertial>
    <visual>
      <origin
        xyz="0 0 0"
        rpy="0 0 0" />
      <geometry>
        <mesh
          filename="package://stretch_description/meshes/link_aruco_right_base.STL" />
      </geometry>
      <material
        name="">
        <color
          rgba="0.792156862745098 0.819607843137255 0.933333333333333 1" />
      </material>
    </visual>
    <collision>
      <origin
        xyz="0 0 0"
        rpy="0 0 0" />
      <geometry>
        <mesh
          filename="package://stretch_description/meshes/link_aruco_right_base.STL" />
      </geometry>
    </collision>
  </link>
  <joint
    name="joint_aruco_right_base"
    type="fixed">
    <origin
      xyz="-0.005 -0.1305 0.15975"
      rpy="0 0 -1.5708" />
    <parent
      link="base_link" />
    <child
      link="link_aruco_right_base" />
    <axis
      xyz="0 0 0" />
  </joint>
  <link
    name="link_aruco_left_base">
    <inertial>
      <origin
        xyz="0 0 -5.00000000014378E-07"
        rpy="0 0 0" />
      <mass
        value="3.59999999990368E-06" />
      <inertia
        ixx="0"
        ixy="0"
        ixz="0"
        iyy="0"
        iyz="0"
        izz="0" />
    </inertial>
    <visual>
      <origin
        xyz="0 0 0"
        rpy="0 0 0" />
      <geometry>
        <mesh
          filename="package://stretch_description/meshes/link_aruco_left_base.STL" />
      </geometry>
      <material
        name="">
        <color
          rgba="0.792156862745098 0.819607843137255 0.933333333333333 1" />
      </material>
    </visual>
    <collision>
      <origin
        xyz="0 0 0"
        rpy="0 0 0" />
      <geometry>
        <mesh
          filename="package://stretch_description/meshes/link_aruco_left_base.STL" />
      </geometry>
    </collision>
  </link>
  <joint
    name="joint_aruco_left_base"
    type="fixed">
    <origin
      xyz="-0.005 0.1305 0.15975"
      rpy="0 0 -1.5708" />
    <parent
      link="base_link" />
    <child
      link="link_aruco_left_base" />
    <axis
      xyz="0 0 0" />
  </joint>
  <link
    name="laser">
    <inertial>
      <origin
        xyz="0 0 -0.000755956127492408"
        rpy="0 0 0" />
      <mass
        value="0.0749979022894495" />
      <inertia
        ixx="0"
        ixy="0"
        ixz="0"
        iyy="0"
        iyz="0"
        izz="0" />
    </inertial>
    <visual>
      <origin
        xyz="0 0 0"
        rpy="0 0 0" />
      <geometry>
        <mesh
          filename="package://stretch_description/meshes/laser.STL" />
      </geometry>
      <material
        name="">
        <color
          rgba="0.250980392156863 0.250980392156863 0.250980392156863 1" />
      </material>
    </visual>
    <collision>
      <origin
        xyz="0 0 0"
        rpy="0 0 0" />
      <geometry>
        <mesh
          filename="package://stretch_description/meshes/laser.STL" />
      </geometry>
    </collision>
  </link>
  <joint
    name="joint_laser"
    type="fixed">
    <origin
      xyz="0.0005028 0 0.1664"
      rpy="0 0 -3.1416" />
    <parent
      link="base_link" />
    <child
      link="laser" />
    <axis
      xyz="0 0 0" />
  </joint>
  <link
    name="link_mast">
    <inertial>
      <origin
        xyz="0.00202736379449595 0.738666520812706 0.00190082388524811"
        rpy="0 0 0" />
      <mass
        value="1.91948632911202" />
      <inertia
        ixx="0.037611756666592"
        ixy="-0.00243755562596598"
        ixz="-0.000148664779854962"
        iyy="0.00029794727672244"
        iyz="-0.00228541318930771"
        izz="0.0376309325010985" />
    </inertial>
    <visual>
      <origin
        xyz="0 0 0"
        rpy="0 0 0" />
      <geometry>
        <mesh
          filename="package://stretch_description/meshes/link_mast.STL" />
      </geometry>
      <material
        name="">
        <color
          rgba="0.792156862745098 0.819607843137255 0.933333333333333 1" />
      </material>
    </visual>
    <collision>
      <origin
        xyz="0 0 0"
        rpy="0 0 0" />
      <geometry>
        <mesh
          filename="package://stretch_description/meshes/link_mast.STL" />
      </geometry>
    </collision>
  </link>
  <joint
    name="joint_mast"
    type="fixed">
    <origin
      xyz="-0.07 0.135 0.0284"
      rpy="1.5708 0 0.0092532" />
    <parent
      link="base_link" />
    <child
      link="link_mast" />
    <axis
      xyz="0 0 0" />
  </joint>
  <link
    name="link_lift">
    <inertial>
      <origin
        xyz="-0.0304705639088444 0.0388789361841112 0.0139034404205229"
        rpy="0 0 0" />
      <mass
        value="0.264121605289143" />
      <inertia
        ixx="0.000224357541444103"
        ixy="3.21433011258325E-06"
        ixz="-3.5541154643512E-05"
        iyy="0.000228213567090214"
        iyz="2.01262019366314E-05"
        izz="7.49643955982455E-06" />
    </inertial>
    <visual>
      <origin
        xyz="0 0 0"
        rpy="0 0 0" />
      <geometry>
        <mesh
          filename="package://stretch_description/meshes/link_lift.STL" />
      </geometry>
      <material
        name="">
        <color
          rgba="0.792156862745098 0.819607843137255 0.933333333333333 1" />
      </material>
    </visual>
    <collision>
      <origin
        xyz="0 0 0"
        rpy="0 0 0" />
      <geometry>
        <mesh
          filename="package://stretch_description/meshes/link_lift.STL" />
      </geometry>
    </collision>
  </link>
  <joint
    name="joint_lift"
    type="prismatic">
    <origin
      xyz="-0.036922 0.16547 -0.00034165"
      rpy="-1.5708 1.5615 -6.2942E-13" />
    <parent
      link="link_mast" />
    <child
      link="link_lift" />
    <axis
      xyz="0 0 1" />
    <limit
      effort="0"
      velocity="0" />
  </joint>
  <link
    name="link_aruco_shoulder">
    <inertial>
      <origin
        xyz="1.38777878078145E-17 0 -0.000124999999999931"
        rpy="0 0 0" />
      <mass
        value="0.000399141592653546" />
      <inertia
        ixx="0"
        ixy="0"
        ixz="0"
        iyy="0"
        iyz="0"
        izz="0" />
    </inertial>
    <visual>
      <origin
        xyz="0 0 0"
        rpy="0 0 0" />
      <geometry>
        <mesh
          filename="package://stretch_description/meshes/link_aruco_shoulder.STL" />
      </geometry>
      <material
        name="">
        <color
          rgba="0.792156862745098 0.819607843137255 0.933333333333333 1" />
      </material>
    </visual>
    <collision>
      <origin
        xyz="0 0 0"
        rpy="0 0 0" />
      <geometry>
        <mesh
          filename="package://stretch_description/meshes/link_aruco_shoulder.STL" />
      </geometry>
    </collision>
  </link>
  <joint
    name="joint_aruco_shoulder"
    type="fixed">
    <origin
      xyz="-0.013377 0.055854 0.086137"
      rpy="-3.5596E-15 -1.5091E-29 -4.2395E-15" />
    <parent
      link="link_lift" />
    <child
      link="link_aruco_shoulder" />
    <axis
      xyz="0 0 0" />
  </joint>
  <link
    name="link_arm_l4">
    <inertial>
      <origin
        xyz="-1.51617165083939E-06 1.45475567348008E-06 -0.089900946600379"
        rpy="0 0 0" />
      <mass
        value="0.0719495626671741" />
      <inertia
        ixx="0.000155311520052461"
        ixy="5.1268759923763E-13"
        ixz="9.10976968335331E-09"
        iyy="0.000155311520094873"
        iyz="-8.74075776503403E-09"
        izz="1.0262519511865E-12" />
    </inertial>
    <visual>
      <origin
        xyz="0 0 0"
        rpy="0 0 0" />
      <geometry>
        <mesh
          filename="package://stretch_description/meshes/link_arm_l4.STL" />
      </geometry>
      <material
        name="">
        <color
          rgba="0.792156862745098 0.819607843137255 0.933333333333333 1" />
      </material>
    </visual>
    <collision>
      <origin
        xyz="0 0 0"
        rpy="0 0 0" />
      <geometry>
        <mesh
          filename="package://stretch_description/meshes/link_arm_l4.STL" />
      </geometry>
    </collision>
  </link>
  <joint
    name="joint_arm_l4"
    type="fixed">
    <origin
      xyz="-0.254705399999994 0 0"
      rpy="1.57079632679491 -3.10190852906344E-16 -1.5707963267949" />
    <parent
      link="link_lift" />
    <child
      link="link_arm_l4" />
    <axis
      xyz="0 0 0" />
  </joint>
  <link
    name="link_arm_l3">
    <inertial>
      <origin
        xyz="-3.1367674827032E-07 2.95352187817954E-07 -0.0915261629566661"
        rpy="0 0 0" />
      <mass
        value="0.0669285264983502" />
      <inertia
        ixx="0.000149479517877408"
        ixy="2.01377864418297E-14"
        ixz="1.7880010854097E-09"
        iyy="0.000149479517879834"
        iyz="-1.68354853507895E-09"
        izz="4.03485617146839E-14" />
    </inertial>
    <visual>
      <origin
        xyz="0 0 0"
        rpy="0 0 0" />
      <geometry>
        <mesh
          filename="package://stretch_description/meshes/link_arm_l3.STL" />
      </geometry>
      <material
        name="">
        <color
          rgba="0.792156862745098 0.819607843137255 0.933333333333333 1" />
      </material>
    </visual>
    <collision>
      <origin
        xyz="0 0 0"
        rpy="0 0 0" />
      <geometry>
        <mesh
          filename="package://stretch_description/meshes/link_arm_l3.STL" />
      </geometry>
    </collision>
  </link>
  <joint
    name="joint_arm_l3"
    type="prismatic">
    <origin
      xyz="0 0 0.0130000000000043"
      rpy="3.57415596539503E-16 3.21228026482375E-16 -2.45647764837286E-16" />
    <parent
      link="link_arm_l4" />
    <child
      link="link_arm_l3" />
    <axis
      xyz="0 0 1" />
  </joint>
  <link
    name="link_arm_l2">
    <inertial>
      <origin
        xyz="-3.10387605451101E-07 2.93865853595587E-07 -0.0914682423202072"
        rpy="0 0 0" />
      <mass
        value="0.0606945644181059" />
      <inertia
        ixx="0.000135738675101982"
        ixy="1.79245510134926E-14"
        ixz="1.60307399677414E-09"
        iyy="0.000135738675103943"
        iyz="-1.51774329254994E-09"
        izz="3.59027442853823E-14" />
    </inertial>
    <visual>
      <origin
        xyz="0 0 0"
        rpy="0 0 0" />
      <geometry>
        <mesh
          filename="package://stretch_description/meshes/link_arm_l2.STL" />
      </geometry>
      <material
        name="">
        <color
          rgba="0.792156862745098 0.819607843137255 0.933333333333333 1" />
      </material>
    </visual>
    <collision>
      <origin
        xyz="0 0 0"
        rpy="0 0 0" />
      <geometry>
        <mesh
          filename="package://stretch_description/meshes/link_arm_l2.STL" />
      </geometry>
    </collision>
  </link>
  <joint
    name="joint_arm_l2"
    type="prismatic">
    <origin
      xyz="0 0 0.013"
      rpy="2.91385731014123E-16 4.44300759504684E-17 3.25691080516352E-16" />
    <parent
      link="link_arm_l3" />
    <child
      link="link_arm_l2" />
    <axis
      xyz="0 0 1" />
  </joint>
  <link
    name="link_arm_l1">
    <inertial>
      <origin
        xyz="-3.16436750941174E-07 2.87317154956668E-07 -0.0913046520301115"
        rpy="0 0 0" />
      <mass
        value="0.0544820428665958" />
      <inertia
        ixx="0.000122350607529029"
        ixy="1.59058187816988E-14"
        ixz="1.46400904807034E-09"
        iyy="0.000122350607532105"
        iyz="-1.32928590402008E-09"
        izz="3.19599843996862E-14" />
    </inertial>
    <visual>
      <origin
        xyz="0 0 0"
        rpy="0 0 0" />
      <geometry>
        <mesh
          filename="package://stretch_description/meshes/link_arm_l1.STL" />
      </geometry>
      <material
        name="">
        <color
          rgba="0.792156862745098 0.819607843137255 0.933333333333333 1" />
      </material>
    </visual>
    <collision>
      <origin
        xyz="0 0 0"
        rpy="0 0 0" />
      <geometry>
        <mesh
          filename="package://stretch_description/meshes/link_arm_l1.STL" />
      </geometry>
    </collision>
  </link>
  <joint
    name="joint_arm_l1"
    type="prismatic">
    <origin
      xyz="0 0 0.013"
      rpy="7.41596560408007E-17 1.33876788296791E-16 -2.44545873596083E-16" />
    <parent
      link="link_arm_l2" />
    <child
      link="link_arm_l1" />
    <axis
      xyz="0 0 1" />
  </joint>
  <link
    name="link_arm_l0">
    <inertial>
      <origin
        xyz="0.0367135919023473 -0.00107228502450457 -0.0198924766917261"
        rpy="0 0 0" />
      <mass
        value="0.161297657884149" />
      <inertia
        ixx="0.00025761027382777"
        ixy="1.8081609912893E-06"
        ixz="-0.000114893620058452"
        iyy="0.000346600936993366"
        iyz="3.72094843174062E-06"
        izz="8.90993408607344E-05" />
    </inertial>
    <visual>
      <origin
        xyz="0 0 0"
        rpy="0 0 0" />
      <geometry>
        <mesh
          filename="package://stretch_description/meshes/link_arm_l0.STL" />
      </geometry>
      <material
        name="">
        <color
          rgba="0.250980392156863 0.250980392156863 0.250980392156863 1" />
      </material>
    </visual>
    <collision>
      <origin
        xyz="0 0 0"
        rpy="0 0 0" />
      <geometry>
        <mesh
          filename="package://stretch_description/meshes/link_arm_l0.STL" />
      </geometry>
    </collision>
  </link>
  <joint
    name="joint_arm_l0"
    type="prismatic">
    <origin
      xyz="0 0 -0.0137499999999938"
      rpy="-3.05317390622457E-16 -4.23236224076729E-16 -2.68425135229209E-17" />
    <parent
      link="link_arm_l1" />
    <child
      link="link_arm_l0" />
    <axis
      xyz="0 0 1" />
  </joint>
  <link
    name="link_aruco_top_wrist">
    <inertial>
      <origin
        xyz="1.38777878078145E-16 2.4980018054066E-16 -0.000124999999998265"
        rpy="0 0 0" />
      <mass
        value="0.000224999999999975" />
      <inertia
        ixx="0"
        ixy="0"
        ixz="0"
        iyy="0"
        iyz="0"
        izz="0" />
    </inertial>
    <visual>
      <origin
        xyz="0 0 0"
        rpy="0 0 0" />
      <geometry>
        <mesh
          filename="package://stretch_description/meshes/link_aruco_top_wrist.STL" />
      </geometry>
      <material
        name="">
        <color
          rgba="0.792156862745098 0.819607843137255 0.933333333333333 1" />
      </material>
    </visual>
    <collision>
      <origin
        xyz="0 0 0"
        rpy="0 0 0" />
      <geometry>
        <mesh
          filename="package://stretch_description/meshes/link_aruco_top_wrist.STL" />
      </geometry>
    </collision>
  </link>
  <joint
    name="joint_aruco_top_wrist"
    type="fixed">
    <origin
      xyz="0.04725 0.029285 0"
      rpy="1.5708 -8.0373E-15 3.1416" />
    <parent
      link="link_arm_l0" />
    <child
      link="link_aruco_top_wrist" />
    <axis
      xyz="0 0 0" />
  </joint>
  <link
    name="link_aruco_inner_wrist">
    <inertial>
      <origin
        xyz="8.32667268468867E-17 1.83186799063151E-15 -0.00012499999999907"
        rpy="0 0 0" />
      <mass
        value="0.000225" />
      <inertia
        ixx="0"
        ixy="0"
        ixz="0"
        iyy="0"
        iyz="0"
        izz="0" />
    </inertial>
    <visual>
      <origin
        xyz="0 0 0"
        rpy="0 0 0" />
      <geometry>
        <mesh
          filename="package://stretch_description/meshes/link_aruco_inner_wrist.STL" />
      </geometry>
      <material
        name="">
        <color
          rgba="0.792156862745098 0.819607843137255 0.933333333333333 1" />
      </material>
    </visual>
    <collision>
      <origin
        xyz="0 0 0"
        rpy="0 0 0" />
      <geometry>
        <mesh
          filename="package://stretch_description/meshes/link_aruco_inner_wrist.STL" />
      </geometry>
    </collision>
  </link>
  <joint
    name="joint_aruco_inner_wrist"
    type="fixed">
    <origin
      xyz="0.04725 -0.0119 -0.02725"
      rpy="3.1416 4.2338E-14 3.1416" />
    <parent
      link="link_arm_l0" />
    <child
      link="link_aruco_inner_wrist" />
    <axis
      xyz="0 0 0" />
  </joint>
  <link
    name="link_wrist_yaw">
    <inertial>
      <origin
        xyz="2.2307877767247E-11 2.0978009180439E-05 -0.0189467005958598"
        rpy="0 0 0" />
      <mass
        value="0.040539898132623" />
      <inertia
        ixx="2.20067641916339E-09"
        ixy="-3.4738587575064E-19"
        ixz="2.85105447397522E-17"
        iyy="2.20034975236097E-09"
        iyz="2.68100954456987E-11"
        izz="3.26666802419496E-13" />
    </inertial>
    <visual>
      <origin
        xyz="0 0 0"
        rpy="0 0 0" />
      <geometry>
        <mesh
          filename="package://stretch_description/meshes/link_wrist_yaw.STL" />
      </geometry>
      <material
        name="">
        <color
          rgba="0.898039215686275 0.917647058823529 0.929411764705882 1" />
      </material>
    </visual>
    <collision>
      <origin
        xyz="0 0 0"
        rpy="0 0 0" />
      <geometry>
        <mesh
          filename="package://stretch_description/meshes/link_wrist_yaw.STL" />
      </geometry>
    </collision>
  </link>
  <joint
    name="joint_wrist_yaw"
    type="revolute">
    <origin
      xyz="0.0830000000000001 -0.0307500000000003 0"
      rpy="-1.5707963267949 -6.04483156485244E-17 3.14159265358979" />
    <parent
      link="link_arm_l0" />
    <child
      link="link_wrist_yaw" />
    <axis
      xyz="0 0 -1" />
  </joint>
  <link
    name="link_gripper">
    <inertial>
      <origin
        xyz="-0.0296515659403755 0.00602125562981548 -0.0433456405357373"
        rpy="0 0 0" />
      <mass
        value="0.0584859625754354" />
      <inertia
        ixx="1.46269710560554E-05"
        ixy="1.259231783619E-06"
        ixz="-4.30356962239059E-06"
        iyy="9.04194214529833E-06"
        iyz="1.50743973258992E-06"
        izz="1.18698303673616E-05" />
    </inertial>
    <visual>
      <origin
        xyz="0 0 0"
        rpy="0 0 0" />
      <geometry>
        <mesh
          filename="package://stretch_description/meshes/link_gripper.STL" />
      </geometry>
      <material
        name="">
        <color
          rgba="0.792156862745098 0.819607843137255 0.933333333333333 1" />
      </material>
    </visual>
    <collision>
      <origin
        xyz="0 0 0"
        rpy="0 0 0" />
      <geometry>
        <mesh
          filename="package://stretch_description/meshes/link_gripper.STL" />
      </geometry>
    </collision>
  </link>
  <joint
    name="joint_gripper"
    type="fixed">
    <origin
      xyz="0 0 0"
      rpy="3.1416 0 1.5708" />
    <parent
      link="link_wrist_yaw" />
    <child
      link="link_gripper" />
    <axis
      xyz="0 0 0" />
  </joint>
  <link
    name="link_gripper_finger_left">
    <inertial>
      <origin
        xyz="0.0945047483510101 0.0124301080924361 -4.44089209850063E-16"
        rpy="0 0 0" />
      <mass
        value="0.0476207785199474" />
      <inertia
        ixx="0"
        ixy="0"
        ixz="0"
        iyy="0"
        iyz="0"
        izz="0" />
    </inertial>
    <visual>
      <origin
        xyz="0 0 0"
        rpy="0 0 0" />
      <geometry>
        <mesh
          filename="package://stretch_description/meshes/link_gripper_finger_left.STL" />
      </geometry>
      <material
        name="">
        <color
          rgba="0.792156862745098 0.819607843137255 0.933333333333333 1" />
      </material>
    </visual>
    <collision>
      <origin
        xyz="0 0 0"
        rpy="0 0 0" />
      <geometry>
        <mesh
          filename="package://stretch_description/meshes/link_gripper_finger_left.STL" />
      </geometry>
    </collision>
  </link>
  <joint
    name="joint_gripper_finger_left"
    type="revolute">
    <origin
      xyz="-0.047231 -0.010151 -0.04679"
      rpy="2.1762E-15 0.5236 3.1416" />
    <parent
      link="link_gripper" />
    <child
      link="link_gripper_finger_left" />
    <axis
      xyz="0 0 1" />
    <limit
      effort="0"
      velocity="0" />
  </joint>
  <link
    name="link_gripper_fingertip_left">
    <inertial>
      <origin
        xyz="-3.16381381648689E-08 -2.91408530639359E-09 0.00812579670381812"
        rpy="0 0 0" />
      <mass
        value="0.00382159917455729" />
      <inertia
        ixx="0"
        ixy="0"
        ixz="0"
        iyy="0"
        iyz="0"
        izz="0" />
    </inertial>
    <visual>
      <origin
        xyz="0 0 0"
        rpy="0 0 0" />
      <geometry>
        <mesh
          filename="package://stretch_description/meshes/link_gripper_fingertip_left.STL" />
      </geometry>
      <material
        name="">
        <color
          rgba="0.250980392156863 0.250980392156863 0.250980392156863 1" />
      </material>
    </visual>
    <collision>
      <origin
        xyz="0 0 0"
        rpy="0 0 0" />
      <geometry>
        <mesh
          filename="package://stretch_description/meshes/link_gripper_fingertip_left.STL" />
      </geometry>
    </collision>
  </link>
  <joint
    name="joint_gripper_fingertip_left"
    type="fixed">
    <origin
      xyz="0.19011 0.014912 0"
      rpy="-1.5708 -4.774E-15 -2.5545" />
    <parent
      link="link_gripper_finger_left" />
    <child
      link="link_gripper_fingertip_left" />
    <axis
      xyz="0 0 0" />
  </joint>
  <link
    name="link_gripper_finger_right">
    <inertial>
      <origin
        xyz="-0.0945047483510099 -0.0124301080924345 0"
        rpy="0 0 0" />
      <mass
        value="0.0476207785199481" />
      <inertia
        ixx="0"
        ixy="0"
        ixz="0"
        iyy="0"
        iyz="0"
        izz="0" />
    </inertial>
    <visual>
      <origin
        xyz="0 0 0"
        rpy="0 0 0" />
      <geometry>
        <mesh
          filename="package://stretch_description/meshes/link_gripper_finger_right.STL" />
      </geometry>
      <material
        name="">
        <color
          rgba="0.792156862745098 0.819607843137255 0.933333333333333 1" />
      </material>
    </visual>
    <collision>
      <origin
        xyz="0 0 0"
        rpy="0 0 0" />
      <geometry>
        <mesh
          filename="package://stretch_description/meshes/link_gripper_finger_right.STL" />
      </geometry>
    </collision>
  </link>
  <joint
    name="joint_gripper_finger_right"
    type="revolute">
    <origin
      xyz="-0.047231 0.010049 -0.04679"
      rpy="3.1416 -0.5236 1.2943E-15" />
    <parent
      link="link_gripper" />
    <child
      link="link_gripper_finger_right" />
    <axis
      xyz="0 0 -1" />
    <limit
      effort="0"
      velocity="0" />
  </joint>
  <link
    name="link_gripper_fingertip_right">
    <inertial>
      <origin
        xyz="2.59386303963494E-08 6.70949018566347E-09 0.00812579516130402"
        rpy="0 0 0" />
      <mass
        value="0.00382160037319545" />
      <inertia
        ixx="0"
        ixy="0"
        ixz="0"
        iyy="0"
        iyz="0"
        izz="0" />
    </inertial>
    <visual>
      <origin
        xyz="0 0 0"
        rpy="0 0 0" />
      <geometry>
        <mesh
          filename="package://stretch_description/meshes/link_gripper_fingertip_right.STL" />
      </geometry>
      <material
        name="">
        <color
          rgba="0.250980392156863 0.250980392156863 0.250980392156863 1" />
      </material>
    </visual>
    <collision>
      <origin
        xyz="0 0 0"
        rpy="0 0 0" />
      <geometry>
        <mesh
          filename="package://stretch_description/meshes/link_gripper_fingertip_right.STL" />
      </geometry>
    </collision>
  </link>
  <joint
    name="joint_gripper_fingertip_right"
    type="fixed">
    <origin
      xyz="-0.19011 -0.014912 0"
      rpy="-1.5708 -2.0539E-15 0.58705" />
    <parent
      link="link_gripper_finger_right" />
    <child
      link="link_gripper_fingertip_right" />
    <axis
      xyz="0 0 0" />
  </joint>
  <link
    name="link_gripper_teleop_mount">
    <inertial>
      <origin
        xyz="3.8266E-05 -0.0044089 0.014934"
        rpy="0 0 0" />
      <mass
        value="0.032535" />
      <inertia
        ixx="1.0206E-05"
        ixy="7.894E-09"
        ixz="-8.5844E-11"
        iyy="7.437E-06"
        iyz="-2.9587E-06"
        izz="2.8384E-06" />
    </inertial>
    <visual>
      <origin
        xyz="0 0 0"
        rpy="0 0 0" />
      <geometry>
        <mesh
          filename="package://stretch_description/meshes/link_gripper_teleop_mount.STL" />
      </geometry>
      <material
        name="">
        <color
          rgba="0.79216 0.81961 0.93333 1" />
      </material>
    </visual>
    <collision>
      <origin
        xyz="0 0 0"
        rpy="0 0 0" />
      <geometry>
        <mesh
          filename="package://stretch_description/meshes/link_gripper_teleop_mount.STL" />
      </geometry>
    </collision>
  </link>
  <joint
    name="joint_gripper_teleop_mount"
    type="fixed">
    <origin
      xyz="-0.10807 0 -0.069789"
      rpy="-0.5236 -4.3792E-15 1.5708" />
    <parent
      link="link_gripper" />
    <child
      link="link_gripper_teleop_mount" />
    <axis
      xyz="0 0 0" />
  </joint>
  <link
    name="link_gripper_teleop_camera">
    <inertial>
      <origin
        xyz="0.0040022 5.9321E-05 -0.00011952"
        rpy="0 0 0" />
      <mass
        value="0.0056257" />
      <inertia
        ixx="0"
        ixy="0"
        ixz="0"
        iyy="0"
        iyz="0"
        izz="0" />
    </inertial>
    <visual>
      <origin
        xyz="0 0 0"
        rpy="0 0 0" />
      <geometry>
        <mesh
          filename="package://stretch_description/meshes/link_gripper_teleop_camera.STL" />
      </geometry>
      <material
        name="">
        <color
          rgba="0.25098 0.25098 0.25098 1" />
      </material>
    </visual>
    <collision>
      <origin
        xyz="0 0 0"
        rpy="0 0 0" />
      <geometry>
        <mesh
          filename="package://stretch_description/meshes/link_gripper_teleop_camera.STL" />
      </geometry>
    </collision>
  </link>
  <joint
    name="joint_gripper_teleop_camera"
    type="fixed">
    <origin
      xyz="0 0.0025 0.029"
      rpy="1.8934E-15 5.5511E-17 1.5708" />
    <parent
      link="link_gripper_teleop_mount" />
    <child
      link="link_gripper_teleop_camera" />
    <axis
      xyz="0 0 0" />
  </joint>
  <link
    name="respeaker_base">
    <inertial>
      <origin
        xyz="0.00765742172691228 0.0007808289319658 -0.0042488298167831"
        rpy="0 0 0" />
      <mass
        value="0.00969129412941461" />
      <inertia
        ixx="4.04210997141871E-07"
        ixy="-2.67330768235362E-08"
        ixz="3.15533543340798E-07"
        iyy="8.9565630098642E-07"
        iyz="3.84519807523401E-08"
        izz="7.08282597380739E-07" />
    </inertial>
    <visual>
      <origin
        xyz="0 0 0"
        rpy="0 0 0" />
      <geometry>
        <mesh
          filename="package://stretch_description/meshes/respeaker_base.STL" />
      </geometry>
      <material
        name="">
        <color
          rgba="0.792156862745098 0.819607843137255 0.933333333333333 1" />
      </material>
    </visual>
    <collision>
      <origin
        xyz="0 0 0"
        rpy="0 0 0" />
      <geometry>
        <mesh
          filename="package://stretch_description/meshes/respeaker_base.STL" />
      </geometry>
    </collision>
  </link>
  <joint
    name="joint_respeaker_base"
    type="fixed">
    <origin
      xyz="1.09074743132875E-05 1.36992 0.00303572796912496"
      rpy="-1.5707963267949 -0.00925318926570022 2.63787745312379E-16" />
    <parent
      link="link_mast" />
    <child
      link="respeaker_base" />
    <axis
      xyz="0 0 0" />
  </joint>
  <link
    name="link_head">
    <inertial>
      <origin
        xyz="0.0385715085631813 0.0438962979592802 0.0285953079074552"
        rpy="0 0 0" />
      <mass
        value="0.112253337408612" />
      <inertia
        ixx="2.02525493348558E-05"
        ixy="4.10612328236778E-07"
        ixz="-3.51294745301548E-06"
        iyy="2.05972547453515E-05"
        iyz="2.33532203756232E-06"
        izz="8.90635591263399E-07" />
    </inertial>
    <visual>
      <origin
        xyz="0 0 0"
        rpy="0 0 0" />
      <geometry>
        <mesh
          filename="package://stretch_description/meshes/link_head.STL" />
      </geometry>
      <material
        name="">
        <color
          rgba="0.792156862745098 0.819607843137255 0.933333333333333 1" />
      </material>
    </visual>
    <collision>
      <origin
        xyz="0 0 0"
        rpy="0 0 0" />
      <geometry>
        <mesh
          filename="package://stretch_description/meshes/link_head.STL" />
      </geometry>
    </collision>
  </link>
  <joint
    name="joint_head"
    type="fixed">
    <origin
      xyz="0 1.33 0"
      rpy="1.57079632679553 -1.5615431375292 3.14159265358916" />
    <parent
      link="link_mast" />
    <child
      link="link_head" />
    <axis
      xyz="0 0 0" />
  </joint>
  <link
    name="link_head_pan">
    <inertial>
      <origin
        xyz="-0.000897771303919936 0.0153115884262233 -0.00355732352622673"
        rpy="0 0 0" />
      <mass
        value="0.0328380131609749" />
      <inertia
        ixx="2.48787398158798E-05"
        ixy="2.91297285206608E-07"
        ixz="-5.01434279444836E-07"
        iyy="1.75849676778684E-05"
        iyz="1.11885430948433E-05"
        izz="7.33087635633834E-06" />
    </inertial>
    <visual>
      <origin
        xyz="0 0 0"
        rpy="0 0 0" />
      <geometry>
        <mesh
          filename="package://stretch_description/meshes/link_head_pan.STL" />
      </geometry>
      <material
        name="">
        <color
          rgba="0.792156862745098 0.819607843137255 0.933333333333333 1" />
      </material>
    </visual>
    <collision>
      <origin
        xyz="0 0 0"
        rpy="0 0 0" />
      <geometry>
        <mesh
          filename="package://stretch_description/meshes/link_head_pan.STL" />
      </geometry>
    </collision>
  </link>
  <joint
    name="joint_head_pan"
    type="revolute">
    <origin
      xyz="0.134999999999989 0.0731000000000006 -0.00299999999999856"
      rpy="-6.49856749449342E-15 -6.06803104015142E-24 1.5707963267949" />
    <parent
      link="link_head" />
    <child
      link="link_head_pan" />
    <axis
      xyz="0 0 1" />
  </joint>
  <link
    name="link_head_tilt">
    <inertial>
      <origin
        xyz="0.00908913559300872 -0.027465225047328 0.0306590945083939"
        rpy="0 0 0" />
      <mass
        value="0.0695347471974854" />
      <inertia
        ixx="1.73800009410866E-05"
        ixy="1.68303503735406E-07"
        ixz="8.0799344254426E-08"
        iyy="4.11644670379791E-05"
        iyz="-9.46859768237946E-07"
        izz="2.38902040246178E-05" />
    </inertial>
    <visual>
      <origin
        xyz="0 0 0"
        rpy="0 0 0" />
      <geometry>
        <mesh
          filename="package://stretch_description/meshes/link_head_tilt.STL" />
      </geometry>
      <material
        name="">
        <color
          rgba="0.792156862745098 0.819607843137255 0.933333333333333 1" />
      </material>
    </visual>
    <collision>
      <origin
        xyz="0 0 0"
        rpy="0 0 0" />
      <geometry>
        <mesh
          filename="package://stretch_description/meshes/link_head_tilt.STL" />
      </geometry>
    </collision>
  </link>
  <joint
    name="joint_head_tilt"
    type="revolute">
    <origin
      xyz="-0.00130000000000119 0.0275069453864393 -0.0533107921694964"
      rpy="1.5707963267949 -9.10382879585826E-15 9.3735145253564E-16" />
    <parent
      link="link_head_pan" />
    <child
      link="link_head_tilt" />
    <axis
      xyz="0 0 1" />
  </joint>
  <link
    name="link_camera">
    <inertial>
      <origin
        xyz="0.0568446557932824 0.766470372536733 0.0945637704764838"
        rpy="0 0 0" />
      <mass
        value="4.49700697914991" />
      <inertia
        ixx="1.03718770186413"
        ixy="0.0877246389213188"
        ixz="-0.000285848102326426"
        iyy="0.083898426850728"
        iyz="-0.0432012163136701"
        izz="1.07815087136755" />
    </inertial>
    <visual>
      <origin
        xyz="0 0 0"
        rpy="0 0 0" />
      <geometry>
        <mesh
          filename="package://stretch_description/meshes/link_camera.STL" />
      </geometry>
      <material
        name="">
        <color
          rgba="0.792156862745098 0.819607843137255 0.933333333333333 1" />
      </material>
    </visual>
    <collision>
      <origin
        xyz="0 0 0"
        rpy="0 0 0" />
      <geometry>
        <mesh
          filename="package://stretch_description/meshes/link_camera.STL" />
      </geometry>
    </collision>
  </link>
  <joint
    name="joint_camera"
    type="fixed">
    <origin
      xyz="0.0202499967221219 -0.0342500000000487 0.0305069453864341"
      rpy="3.14159265358979 1.5707963267949 0" />
    <parent
      link="link_head_tilt" />
    <child
      link="link_camera" />
    <axis
      xyz="0 0 0" />
  </joint>
  <link
    name="link_head_teleop_mount">
    <inertial>
      <origin
        xyz="0.032675 0.036403 -0.0035184"
        rpy="0 0 0" />
      <mass
        value="0.072645" />
      <inertia
        ixx="9.371E-05"
        ixy="-3.7238E-05"
        ixz="1.2184E-05"
        iyy="2.7972E-05"
        iyz="2.6994E-05"
        izz="9.9358E-05" />
    </inertial>
    <visual>
      <origin
        xyz="0 0 0"
        rpy="0 0 0" />
      <geometry>
        <mesh
          filename="package://stretch_description/meshes/link_head_teleop_mount.STL" />
      </geometry>
      <material
        name="">
        <color
          rgba="0.79216 0.81961 0.93333 1" />
      </material>
    </visual>
    <collision>
      <origin
        xyz="0 0 0"
        rpy="0 0 0" />
      <geometry>
        <mesh
          filename="package://stretch_description/meshes/link_head_teleop_mount.STL" />
      </geometry>
    </collision>
  </link>
  <joint
    name="joint_head_teleop_mount"
    type="fixed">
    <origin
      xyz="0.079 0.0731 0.052"
      rpy="0 0 0" />
    <parent
      link="link_head" />
    <child
      link="link_head_teleop_mount" />
    <axis
      xyz="0 0 0" />
  </joint>
  <link
    name="link_head_teleop_camera">
    <inertial>
      <origin
        xyz="0.0040022 5.9321E-05 -0.00011952"
        rpy="0 0 0" />
      <mass
        value="0.0056257" />
      <inertia
        ixx="0"
        ixy="0"
        ixz="0"
        iyy="0"
        iyz="0"
        izz="0" />
    </inertial>
    <visual>
      <origin
        xyz="0 0 0"
        rpy="0 0 0" />
      <geometry>
        <mesh
          filename="package://stretch_description/meshes/link_head_teleop_camera.STL" />
      </geometry>
      <material
        name="">
        <color
          rgba="0.25098 0.25098 0.25098 1" />
      </material>
    </visual>
    <collision>
      <origin
        xyz="0 0 0"
        rpy="0 0 0" />
      <geometry>
        <mesh
          filename="package://stretch_description/meshes/link_head_teleop_camera.STL" />
      </geometry>
    </collision>
  </link>
  <joint
    name="joint_head_teleop_camera"
    type="fixed">
    <origin
      xyz="0.055997 0.088091 -0.0245"
      rpy="1.5708 1.5708 0" />
    <parent
      link="link_head_teleop_mount" />
    <child
      link="link_head_teleop_camera" />
    <axis
      xyz="0 0 0" />
  </joint>
</robot>